Workbook

Sheet Summary
B2: Commodity Processing Unit
B3: Raw Receiving & Purchased Finished Commodities Delivery Report - Sudan
B4: Season 2025-2026
B6: Commodity | C6: Code | D6: Region | E6: Supplier | F6: PO# | G6: Receiving Location | H6: Received Weight-MT | I6: Purchasing Weight-MT | J6: Purchasing Balance | K6: PO Status | L6: Job Status | M6: Responsible Person
B7: GS-Above Medium Quality | C7: SM0101 | D7: Gadarif | E7: Mohd Karamallah | F7: 1763 | G7: Gadarif WH-AG | H7: =GETPIVOTDATA(" Weight MT",GS!$N$2,"Receiving Location","Gadarif WH-AG","PO#","PO#1763","Grade","Above Medium Quality") -> 83.78 | I7: =Table4[[#This Row],[Received Weight-MT]] -> 83.78 | J7: =Table4[[#This Row],[Received Weight-MT]]-Table4[[#This Row],[Purchasing Weight-MT]] -> 0 | K7: Completed | L7: Ongoing | M7: Abubaker Mahjoub
B8: GS-Above Medium Quality | C8: SM0101 | D8: Gadarif | E8: Mohd Karamallah | F8: 1763 | G8: Organica Sifter | H8: =GETPIVOTDATA(" Weight MT",GS!$N$2,"Receiving Location","Organica Sifter","PO#","PO#1763","Grade","Above Medium Quality") -> 229.58 | I8: =Table4[[#This Row],[Received Weight-MT]] -> 229.58 | J8: =Table4[[#This Row],[Received Weight-MT]]-Table4[[#This Row],[Purchasing Weight-MT]] -> 0 | K8: Completed | L8: Ongoing | M8: Ahmed Abdalah
B9: GS-Above Medium Quality | C9: 1000000040 | D9: Gadarif | E9: Mohd Karamallah | F9: 4500000384 | G9: Gadarif WH | H9: =GETPIVOTDATA(" Weight MT",GS!$N$2,"Receiving Location","Gadarif WH","PO#","PO#4500000384","Grade","Above Medium Quality") -> 851.68 | I9: =Table4[[#This Row],[Received Weight-MT]] -> 851.68 | J9: =Table4[[#This Row],[Received Weight-MT]]-Table4[[#This Row],[Purchasing Weight-MT]] -> 0 | K9: Completed | M9: Abubaker Mahjoub
B10: GS-Above Medium Quality | C10: 1000000040 | D10: Gadarif | E10: Mohd Karamallah | F10: 4500001491 | G10: Gadarif WH | H10: =GETPIVOTDATA(" Weight MT",GS!$N$2,"Receiving Location","Gadarif WH","PO#","PO#4500001491","Grade","Above Medium Quality") -> 760.44 | I10: =Table4[[#This Row],[Received Weight-MT]] -> 760.44 | J10: =Table4[[#This Row],[Received Weight-MT]]-Table4[[#This Row],[Purchasing Weight-MT]] -> 0 | K10: Completed | M10: Abubaker Mahjoub
B11: GS-Above Medium Quality | C11: 1000000040 | D11: PZU | E11: Mohd Karamallah | F11: 4500001655 | G11: Balaji Sifter | H11: =GETPIVOTDATA(" Weight MT",GS!$N$2,"Receiving Location","Balaji Sifter","Grade","Above Medium Quality") -> 260.28 | I11: =Table4[[#This Row],[Received Weight-MT]] -> 260.28 | J11: =Table4[[#This Row],[Received Weight-MT]]-Table4[[#This Row],[Purchasing Weight-MT]] -> 0 | K11: Completed | M11: Mohd Elmustafa
B12: Sorghum-RM | C12: 1000000037 | D12: Gadarif | E12: Mohd Karamallah | F12: 4500000001 | G12: Concrete Silo | H12: =GETPIVOTDATA(" Weight MT",Sorghum!$L$2,"Receiving Location","Concrete Silo","PO#",4500000001) -> 5000.61 | I12: =Table4[[#This Row],[Received Weight-MT]] -> 5000.61 | J12: =Table4[[#This Row],[Received Weight-MT]]-Table4[[#This Row],[Purchasing Weight-MT]] -> 0 | K12: Completed | M12: Ahmed Abdalah
B13: Sorghum-Raw | C13: 1000000037 | D13: Gadarif | E13: Mohd Karamallah | F13: 4500000293 | G13: Concrete Silo | H13: =GETPIVOTDATA(" Weight MT",Sorghum!$L$2,"Receiving Location","Concrete Silo","PO#",4500000293) -> 2500 | I13: 2500 | J13: =Table4[[#This Row],[Received Weight-MT]]-Table4[[#This Row],[Purchasing Weight-MT]] -> 0 | K13: Completed | M13: Ahmed Abdalah
B14: Sorghum-Raw | C14: 1000000037 | D14: Gadarif | E14: Mohd Karamallah | F14: 4500000294 | G14: Concrete Silo | H14: =GETPIVOTDATA(" Weight MT",Sorghum!$L$2,"Receiving Location","Concrete Silo","Commodity","Sorghum-RM","PO#",4500000294) -> 2020 | I14: 2020 | J14: =Table4[[#This Row],[Received Weight-MT]]-Table4[[#This Row],[Purchasing Weight-MT]] -> 0 | K14: Completed | M14: Ahmed Abdalah
B15: Sorghum-Raw | C15: 1000000037 | D15: Gadarif | E15: Mohd Karamallah | F15: 4500000567 | G15: Five Stars Sifter | H15: =GETPIVOTDATA(" Weight MT",Sorghum!$L$2,"Receiving Location","Five Stars Sifter","Commodity","Sorghum-RM","PO#",4500000567) -> 1569.98 | I15: =Table4[[#This Row],[Received Weight-MT]] -> 1569.98 | J15: =Table4[[#This Row],[Received Weight-MT]]-Table4[[#This Row],[Purchasing Weight-MT]] -> 0 | K15: Completed | M15: Feras Ibrahim
B16: Sorghum-FG | C16: 4000000232 | D16: Gadarif | E16: Mohd Karamallah | F16: 4500000294 | G16: Concrete Silo | H16: =GETPIVOTDATA(" Weight MT",Sorghum!$L$2,"Receiving Location","Concrete Silo","Commodity","Sorghum-FG","PO#",4500000294) -> 480 | I16: 480 | J16: =Table4[[#This Row],[Received Weight-MT]]-Table4[[#This Row],[Purchasing Weight-MT]] -> 0 | K16: Completed | M16: Ahmed Abdalah
B17: Pigeon Peas-FG | C17: 4000000059 | D17: PZU | E17: Abdallah Abdealziz | F17: 4500001484 | G17: PZU WH-A013 | H17: =GETPIVOTDATA(" Weight MT",'Pigeon Peas'!$N$2,"Receiving Location","PZU WH-A013","Commodity Code",4000000059,"Supplier Name","Abdallah Abdealziz","PO#","PO#4500001484") -> 724.46 | I17: =Table4[[#This Row],[Received Weight-MT]] -> 724.46 | J17: =Table4[[#This Row],[Received Weight-MT]]-Table4[[#This Row],[Purchasing Weight-MT]] -> 0 | K17: Ongoing | M17: Aljaali Sabahalkheir
B18: Pigeon Peas-FG | C18: 4000000059 | D18: PZU | E18: Abdallah Abdealziz | F18: 4500001654 | G18: PZU WH-A013 | H18: =GETPIVOTDATA(" Weight MT",'Pigeon Peas'!$N$2,"Receiving Location","PZU WH-A013","Commodity Code",4000000059,"Supplier Name","Abdallah Abdealziz","PO#","PO#4500001654") -> 1540.08 | I18: =Table4[[#This Row],[Received Weight-MT]] -> 1540.08 | J18: =Table4[[#This Row],[Received Weight-MT]]-Table4[[#This Row],[Purchasing Weight-MT]] -> 0 | K18: Ongoing | M18: Aljaali Sabahalkheir
B19: Pigeon Peas-FG | C19: 4000000059 | D19: PZU | E19: Magdi Gournas | F19: 4500001652 | G19: PZU WH-A013 | H19: =GETPIVOTDATA(" Weight MT",'Pigeon Peas'!$N$2,"Receiving Location","PZU WH-A013","Commodity Code",4000000059,"Supplier Name","Magdi Gournas","PO#","PO#4500001652") -> 898 | I19: =Table4[[#This Row],[Received Weight-MT]] -> 898 | J19: =Table4[[#This Row],[Received Weight-MT]]-Table4[[#This Row],[Purchasing Weight-MT]] -> 0 | K19: Ongoing | M19: Aljaali Sabahalkheir
B20: Pigeon Peas-FG | C20: 4000000059 | D20: PZU | E20: Mohd Karamallah | F20: 4500002146 | G20: PZU WH-A013 | H20: =GETPIVOTDATA(" Weight MT",'Pigeon Peas'!$N$2,"Receiving Location","PZU WH-A013","Commodity Code",4000000059,"Supplier Name","Mohd Karmallah","PO#","PO#4500002146") -> 199.7 | I20: =Table4[[#This Row],[Received Weight-MT]] -> 199.7 | J20: =Table4[[#This Row],[Received Weight-MT]]-Table4[[#This Row],[Purchasing Weight-MT]] -> 0 | K20: Completed | M20: Aljaali Sabahalkheir
B21: Pigeon Peas-FG | C21: 4000000059 | D21: PZU | E21: Abdallah Abdealziz | F21: 4500005939 | G21: PZU WH-A013 | H21: =GETPIVOTDATA(" Weight MT",'Pigeon Peas'!$N$2,"Receiving Location","PZU WH-A013","Commodity Code",4000000059,"Supplier Name","Abdallah Abdealziz","PO#","PO#4500005939") -> 551.08 | I21: =Table4[[#This Row],[Received Weight-MT]] -> 551.08 | J21: =Table4[[#This Row],[Received Weight-MT]]-Table4[[#This Row],[Purchasing Weight-MT]] -> 0 | K21: Ongoing | M21: Aljaali Sabahalkheir
B22: Pigeon Peas-RM | C22: 1000000035 | D22: New Halfa | E22: Magdi Gournas | F22: 4500005740 | G22: NH-Agent WH | H22: =GETPIVOTDATA(" Weight MT",'Pigeon Peas'!$N$2,"Receiving Location","NH-Agent WH","Commodity Code",1000000035,"Supplier Name","Magdi Gournas","PO#","PO#4500005740") -> 315 | I22: 350 | J22: =Table4[[#This Row],[Received Weight-MT]]-Table4[[#This Row],[Purchasing Weight-MT]] -> -35 | K22: Ongoing | M22: Aljaali Sabahalkheir
B23: WSNG-Eastern | C23: 1000000041 | D23: PZU | E23: Abdallah Abdealziz | F23: 4500002362 | G23: Balaji Sifter | H23: =GETPIVOTDATA(" Weight MT",WSNG!$N$2,"Receiving Location","Balaji Sifter","Supplier Name","Abdallah Abdealziz","PO#","PO#4500002362") -> 333.84 | I23: 350 | J23: =Table4[[#This Row],[Received Weight-MT]]-Table4[[#This Row],[Purchasing Weight-MT]] -> -16.16 | K23: Ongoing | M23: Mohd Elmustafa
B24: Gum Arabic Talha-RM | C24: 1000000033 | D24: KHT-Baghier | E24: Abdallah Abdealziz | F24: 4500006403 | G24: Baghier WH | H24: =GETPIVOTDATA(" Weight MT",'Gum Arabic'!$L$2,"Receiving Location","Baghier WH","PO#",4500006403) -> 245.247 | I24: =Table4[[#This Row],[Received Weight-MT]] -> 245.247 | J24: =Table4[[#This Row],[Received Weight-MT]]-Table4[[#This Row],[Purchasing Weight-MT]] -> 0 | K24: Ongoing | M24: Yousif Mohd

Sheet GS
A1: Date | B1: Receiving Location | C1: Truck No. | D1: Jute Bags | E1: BP Bags | F1: SP Bags | G1: Weight MT | H1: Weight KG | I1: Commodity Code | J1: Supplier Name | K1: PO# | L1: Grade | N1: Summary
A2: 46001 | B2: Gadarif WH-AG | C2: 62100 | D2: 65 | G2: 5.66 | H2: =Table3[[#This Row],[Weight MT]]*100 -> 566 | I2: SM0101 | J2: Mohd Karamallah | K2: 1763 | L2: Above Medium Quality | N2: Receiving Location | O2: Weight MT | P2: Jute Bags | Q2: Truck No.
A3: 46001 | B3: Gadarif WH-AG | C3: 1861 | D3: 68 | G3: 5.84 | H3: =Table3[[#This Row],[Weight MT]]*100 -> 584 | I3: SM0101 | J3: Mohd Karamallah | K3: 1763 | L3: Above Medium Quality | N3: Gadarif WH-AG | O3: 83.78 | P3: 970 | Q3: 9
A4: 46001 | B4: Gadarif WH-AG | C4: 71107 | D4: 160 | G4: 14.14 | H4: =Table3[[#This Row],[Weight MT]]*100 -> 1414 | I4: SM0101 | J4: Mohd Karamallah | K4: 1763 | L4: Above Medium Quality | N4: Above Medium Quality | O4: 83.78 | P4: 970 | Q4: 9
A5: 46001 | B5: Gadarif WH-AG | C5: 1862 | D5: 66 | G5: 5.68 | H5: =Table3[[#This Row],[Weight MT]]*100 -> 568 | I5: SM0101 | J5: Mohd Karamallah | K5: 1763 | L5: Above Medium Quality | N5: PO#1763 | O5: 83.78 | P5: 970 | Q5: 9
A6: 46001 | B6: Gadarif WH-AG | C6: 3390 | D6: 69 | G6: 5.98 | H6: =Table3[[#This Row],[Weight MT]]*100 -> 598 | I6: SM0101 | J6: Mohd Karamallah | K6: 1763 | L6: Above Medium Quality | N6: Organica Sifter | O6: 229.58 | P6: 2630 | Q6: 16
A7: 46001 | B7: Gadarif WH-AG | C7: 5914 | D7: 70 | G7: 5.94 | H7: =Table3[[#This Row],[Weight MT]]*100 -> 594 | I7: SM0101 | J7: Mohd Karamallah | K7: 1763 | L7: Above Medium Quality | N7: Above Medium Quality | O7: 229.58 | P7: 2630 | Q7: 16
A8: 46001 | B8: Gadarif WH-AG | C8: 48464 | D8: 65 | G8: 5.66 | H8: =Table3[[#This Row],[Weight MT]]*100 -> 566 | I8: SM0101 | J8: Mohd Karamallah | K8: 1763 | L8: Above Medium Quality | N8: PO#1763 | O8: 229.58 | P8: 2630 | Q8: 16
A9: 46002 | B9: Gadarif WH-AG | C9: 48844 | D9: 267 | G9: 23.02 | H9: =Table3[[#This Row],[Weight MT]]*100 -> 2302 | I9: SM0101 | J9: Mohd Karamallah | K9: 1763 | L9: Above Medium Quality | N9: Gadarif WH | O9: 1612.12 | P9: 17391 | Q9: 168
A10: 46002 | B10: Gadarif WH-AG | C10: 20290 | D10: 140 | G10: 11.86 | H10: =Table3[[#This Row],[Weight MT]]*100 -> 1186 | I10: SM0101 | J10: Mohd Karamallah | K10: 1763 | L10: Above Medium Quality | N10: Above Medium Quality | O10: 1612.12 | P10: 17391 | Q10: 168
A11: 46012 | B11: Organica Sifter | C11: 1187 | D11: 150 | G11: =Table3[[#This Row],[Weight KG]]/1000 -> 13.1 | H11: 13100 | I11: SM0101 | J11: Mohd Karamallah | K11: 1763 | L11: Above Medium Quality | N11: PO#4500000384 | O11: 851.68 | P11: 9209 | Q11: 106
A12: 46012 | B12: Organica Sifter | C12: 4722 | D12: 150 | G12: =Table3[[#This Row],[Weight KG]]/1000 -> 12.84 | H12: 12840 | I12: SM0101 | J12: Mohd Karamallah | K12: 1763 | L12: Above Medium Quality | N12: PO#4500001491 | O12: 760.44 | P12: 8182 | Q12: 62
A13: 46012 | B13: Organica Sifter | C13: 1187 | D13: 150 | G13: =Table3[[#This Row],[Weight KG]]/1000 -> 12.82 | H13: 12820 | I13: SM0101 | J13: Mohd Karamallah | K13: 1763 | L13: Above Medium Quality | N13: Balaji Sifter | O13: 260.28 | P13: 3050 | Q13: 6
A14: 46012 | B14: Organica Sifter | C14: 368 | D14: 150 | G14: =Table3[[#This Row],[Weight KG]]/1000 -> 13.28 | H14: 13280 | I14: SM0101 | J14: Mohd Karamallah | K14: 1763 | L14: Above Medium Quality | N14: Above Medium Quality | O14: 260.28 | P14: 3050 | Q14: 6
A15: 46012 | B15: Organica Sifter | C15: 4722 | D15: 150 | G15: =Table3[[#This Row],[Weight KG]]/1000 -> 12.9 | H15: 12900 | I15: SM0101 | J15: Mohd Karamallah | K15: 1763 | L15: Above Medium Quality | N15: PO34500001655 | O15: 260.28 | P15: 3050 | Q15: 6
A16: 46012 | B16: Organica Sifter | C16: 80762 | D16: 150 | G16: =Table3[[#This Row],[Weight KG]]/1000 -> 12.92 | H16: 12920 | I16: SM0101 | J16: Mohd Karamallah | K16: 1763 | L16: Above Medium Quality | N16: Grand Total | O16: 2185.76 | P16: 24041 | Q16: 199
A17: 46012 | B17: Organica Sifter | C17: 80762 | D17: 150 | G17: =Table3[[#This Row],[Weight KG]]/1000 -> 12.96 | H17: 12960 | I17: SM0101 | J17: Mohd Karamallah | K17: 1763 | L17: Above Medium Quality
A18: 46012 | B18: Organica Sifter | C18: 4722 | D18: 150 | G18: =Table3[[#This Row],[Weight KG]]/1000 -> 13.24 | H18: 13240 | I18: SM0101 | J18: Mohd Karamallah | K18: 1763 | L18: Above Medium Quality
A19: 46014 | B19: Organica Sifter | C19: 80762 | D19: 170 | G19: =Table3[[#This Row],[Weight KG]]/1000 -> 14.66 | H19: 14660 | I19: SM0101 | J19: Mohd Karamallah | K19: 1763 | L19: Above Medium Quality
A20: 46014 | B20: Organica Sifter | C20: 1387 | D20: 170 | G20: =Table3[[#This Row],[Weight KG]]/1000 -> 14.68 | H20: 14680 | I20: SM0101 | J20: Mohd Karamallah | K20: 1763 | L20: Above Medium Quality
A21: 46014 | B21: Organica Sifter | C21: 80762 | D21: 185 | G21: =Table3[[#This Row],[Weight KG]]/1000 -> 16.34 | H21: 16340 | I21: SM0101 | J21: Mohd Karamallah | K21: 1763 | L21: Above Medium Quality
A22: 46014 | B22: Organica Sifter | C22: 1387 | D22: 185 | G22: =Table3[[#This Row],[Weight KG]]/1000 -> 16.32 | H22: 16320 | I22: SM0101 | J22: Mohd Karamallah | K22: 1763 | L22: Above Medium Quality
A23: 46014 | B23: Organica Sifter | C23: 4722 | D23: 170 | G23: =Table3[[#This Row],[Weight KG]]/1000 -> 14.7 | H23: 14700 | I23: SM0101 | J23: Mohd Karamallah | K23: 1763 | L23: Above Medium Quality
A24: 46014 | B24: Organica Sifter | C24: 16429 | D24: 185 | G24: =Table3[[#This Row],[Weight KG]]/1000 -> 16.5 | H24: 16500 | I24: SM0101 | J24: Mohd Karamallah | K24: 1763 | L24: Above Medium Quality
A25: 46014 | B25: Organica Sifter | C25: 4722 | D25: 185 | G25: =Table3[[#This Row],[Weight KG]]/1000 -> 15.8 | H25: 15800 | I25: SM0101 | J25: Mohd Karamallah | K25: 1763 | L25: Above Medium Quality
A26: 46015 | B26: Organica Sifter | C26: 1187 | D26: 180 | G26: =Table3[[#This Row],[Weight KG]]/1000 -> 16.52 | H26: 16520 | I26: SM0101 | J26: Mohd Karamallah | K26: 1763 | L26: Above Medium Quality
A27: 46051 | B27: Gadarif WH | C27: 1364 | D27: 120 | G27: 11.62 | H27: =Table3[[#This Row],[Weight MT]]*100 -> 1162 | I27: 1000000040 | J27: Mohd Karamallah | K27: 4500000384 | L27: Above Medium Quality
A28: 46051 | B28: Gadarif WH | C28: 467 | D28: 80 | G28: 7.7 | H28: =Table3[[#This Row],[Weight MT]]*100 -> 770 | I28: 1000000040 | J28: Mohd Karamallah | K28: 4500000384 | L28: Above Medium Quality
A29: 46053 | B29: Gadarif WH | C29: 42209 | D29: 100 | G29: 9.48 | H29: =Table3[[#This Row],[Weight MT]]*100 -> 948 | I29: 1000000040 | J29: Mohd Karamallah | K29: 4500000384 | L29: Above Medium Quality
A30: 46053 | B30: Gadarif WH | C30: 663 | D30: 80 | G30: 7.55 | H30: =Table3[[#This Row],[Weight MT]]*100 -> 755 | I30: 1000000040 | J30: Mohd Karamallah | K30: 4500000384 | L30: Above Medium Quality
A31: 46053 | B31: Gadarif WH | C31: 303 | D31: 80 | G31: 7.62 | H31: =Table3[[#This Row],[Weight MT]]*100 -> 762 | I31: 1000000040 | J31: Mohd Karamallah | K31: 4500000384 | L31: Above Medium Quality
A32: 46053 | B32: Gadarif WH | C32: 264 | D32: 80 | G32: 7.55 | H32: =Table3[[#This Row],[Weight MT]]*100 -> 755 | I32: 1000000040 | J32: Mohd Karamallah | K32: 4500000384 | L32: Above Medium Quality
A33: 46053 | B33: Gadarif WH | C33: 711 | D33: 80 | G33: 7.46 | H33: =Table3[[#This Row],[Weight MT]]*100 -> 746 | I33: 1000000040 | J33: Mohd Karamallah | K33: 4500000384 | L33: Above Medium Quality
A34: 46054 | B34: Gadarif WH | C34: 769 | D34: 80 | G34: 7.5 | H34: =Table3[[#This Row],[Weight MT]]*100 -> 750 | I34: 1000000040 | J34: Mohd Karamallah | K34: 4500000384 | L34: Above Medium Quality
A35: 46054 | B35: Gadarif WH | C35: 19913 | D35: 80 | G35: 7.78 | H35: =Table3[[#This Row],[Weight MT]]*100 -> 778 | I35: 1000000040 | J35: Mohd Karamallah | K35: 4500000384 | L35: Above Medium Quality
A36: 46055 | B36: Gadarif WH | C36: 3487 | D36: 200 | G36: 18.28 | H36: =Table3[[#This Row],[Weight MT]]*100 -> 1828 | I36: 1000000040 | J36: Mohd Karamallah | K36: 4500000384 | L36: Above Medium Quality
A37: 46055 | B37: Gadarif WH | C37: 4164 | D37: 200 | G37: 18.26 | H37: =Table3[[#This Row],[Weight MT]]*100 -> 1826 | I37: 1000000040 | J37: Mohd Karamallah | K37: 4500000384 | L37: Above Medium Quality
A38: 46055 | B38: Gadarif WH | C38: 3952 | D38: 200 | G38: 18.02 | H38: =Table3[[#This Row],[Weight MT]]*100 -> 1802 | I38: 1000000040 | J38: Mohd Karamallah | K38: 4500000384 | L38: Above Medium Quality
... A186: 46127 | B186: Gadarif WH | C186: 19913 | D186: 85 | G186: 8 | H186: =Table3[[#This Row],[Weight MT]]*100 -> 800 | I186: 1000000040 | J186: Mohd Karamallah | K186: 4500001491 | L186: Above Medium Quality
A187: 46120 | B187: Balaji Sifter | C187: 4236 | D187: 500 | G187: =Table3[[#This Row],[Weight KG]]/1000 -> 44.6 | H187: 44600 | I187: 1000000040 | J187: Mohd Karamallah | K187: 4500001655 | L187: Above Medium Quality
...

Sheet Sorghum
A1: Date | B1: Receiving Location | C1: Truck No. | D1: Jute Bags/Bulk | E1: Weight MT | F1: Weight KG | G1: Commodity | H1: Commodity Code | I1: Supplier Name | J1: PO# | L1: Summary
A2: 46034 | B2: Concrete Silo | D2: Bulk | E2: 2922.61 | F2: =Table5[[#This Row],[Weight MT]]*1000 -> 2922610 | G2: Sorghum-RM | H2: 1000000037 | I2: Mohd Karamallah | J2: 4500000001 | L2: Receiving Location | M2: Weight MT | N2: Jute Bags/Bulk | O2: Truck No.
A3: 46035 | B3: Concrete Silo | D3: Bulk | E3: 2078 | F3: =Table5[[#This Row],[Weight MT]]*1000 -> 2078000 | G3: Sorghum-RM | H3: 1000000037 | I3: Mohd Karamallah | J3: 4500000001 | L3: Concrete Silo | M3: 10000.61 | N3: 0
A4: 46041 | B4: Concrete Silo | D4: Bulk | E4: 1942 | F4: =Table5[[#This Row],[Weight MT]]*1000 -> 1942000 | G4: Sorghum-RM | H4: 1000000037 | I4: Mohd Karamallah | J4: 4500000294 | L4: Sorghum-FG
A5: 46043 | B5: Concrete Silo | D5: Bulk | E5: 78 | F5: =Table5[[#This Row],[Weight MT]]*1000 -> 78000 | G5: Sorghum-RM | H5: 1000000037 | I5: Mohd Karamallah | J5: 4500000294 | L5: 4500000294 | M5: 480 | N5: 0
A6: 46043 | B6: Concrete Silo | D6: Bulk | E6: 480 | F6: =Table5[[#This Row],[Weight MT]]*1000 -> 480000 | G6: Sorghum-FG | H6: 4000000232 | I6: Mohd Karamallah | J6: 4500000294 | L6: Jan
A7: 46058 | B7: Concrete Silo | D7: Bulk | E7: 2500 | F7: =Table5[[#This Row],[Weight MT]]*1000 -> 2500000 | G7: Sorghum-RM | H7: 1000000037 | I7: Mohd Karamallah | J7: 4500000293 | L7: 21-Jan | M7: 480 | N7: 0
A8: 46063 | B8: Five Stars Sifter | C8: 264 | D8: 80 | E8: =Table5[[#This Row],[Weight KG]]/1000 -> 8.02 | F8: 8020 | G8: Sorghum-RM | H8: 1000000037 | I8: Mohd Karamallah | J8: 4500000567 | L8: Sorghum-RM
A9: 46063 | B9: Five Stars Sifter | C9: 737 | D9: 80 | E9: =Table5[[#This Row],[Weight KG]]/1000 -> 8.02 | F9: 8020 | G9: Sorghum-RM | H9: 1000000037 | I9: Mohd Karamallah | J9: 4500000567 | L9: 4500000001 | M9: 5000.61 | N9: 0
A10: 46063 | B10: Five Stars Sifter | C10: 1110 | D10: 80 | E10: =Table5[[#This Row],[Weight KG]]/1000 -> 7.96 | F10: 7960 | G10: Sorghum-RM | H10: 1000000037 | I10: Mohd Karamallah | J10: 4500000567 | L10: Jan
A11: 46063 | B11: Five Stars Sifter | C11: 1802 | D11: 80 | E11: =Table5[[#This Row],[Weight KG]]/1000 -> 8.06 | F11: 8060 | G11: Sorghum-RM | H11: 1000000037 | I11: Mohd Karamallah | J11: 4500000567 | L11: 12-Jan | M11: 2922.61 | N11: 0
A12: 46063 | B12: Five Stars Sifter | C12: 2226 | D12: 80 | E12: =Table5[[#This Row],[Weight KG]]/1000 -> 7.98 | F12: 7980 | G12: Sorghum-RM | H12: 1000000037 | I12: Mohd Karamallah | J12: 4500000567 | L12: 13-Jan | M12: 2078 | N12: 0
A13: 46063 | B13: Five Stars Sifter | C13: 573 | D13: 80 | E13: =Table5[[#This Row],[Weight KG]]/1000 -> 7.88 | F13: 7880 | G13: Sorghum-RM | H13: 1000000037 | I13: Mohd Karamallah | J13: 4500000567 | L13: 4500000293 | M13: 2500 | N13: 0
A14: 46063 | B14: Five Stars Sifter | C14: 264 | D14: 80 | E14: =Table5[[#This Row],[Weight KG]]/1000 -> 7.98 | F14: 7980 | G14: Sorghum-RM | H14: 1000000037 | I14: Mohd Karamallah | J14: 4500000567 | L14: Feb
A15: 46063 | B15: Five Stars Sifter | C15: 343 | D15: 80 | E15: =Table5[[#This Row],[Weight KG]]/1000 -> 7.9 | F15: 7900 | G15: Sorghum-RM | H15: 1000000037 | I15: Mohd Karamallah | J15: 4500000567 | L15: 05-Feb | M15: 2500 | N15: 0
A16: 46063 | B16: Five Stars Sifter | C16: 263 | D16: 80 | E16: =Table5[[#This Row],[Weight KG]]/1000 -> 7.86 | F16: 7860 | G16: Sorghum-RM | H16: 1000000037 | I16: Mohd Karamallah | J16: 4500000567 | L16: 4500000294 | M16: 2020 | N16: 0
A17: 46063 | B17: Five Stars Sifter | C17: 1606 | D17: 80 | E17: =Table5[[#This Row],[Weight KG]]/1000 -> 7.86 | F17: 7860 | G17: Sorghum-RM | H17: 1000000037 | I17: Mohd Karamallah | J17: 4500000567 | L17: Jan
A18: 46063 | B18: Five Stars Sifter | C18: 62023 | D18: 80 | E18: =Table5[[#This Row],[Weight KG]]/1000 -> 8 | F18: 8000 | G18: Sorghum-RM | H18: 1000000037 | I18: Mohd Karamallah | J18: 4500000567 | L18: 19-Jan | M18: 1942 | N18: 0
A19: 46063 | B19: Five Stars Sifter | C19: 41109 | D19: 80 | E19: =Table5[[#This Row],[Weight KG]]/1000 -> 8.04 | F19: 8040 | G19: Sorghum-RM | H19: 1000000037 | I19: Mohd Karamallah | J19: 4500000567 | L19: 21-Jan | M19: 78 | N19: 0
A20: 46063 | B20: Five Stars Sifter | C20: 1056 | D20: 80 | E20: =Table5[[#This Row],[Weight KG]]/1000 -> 7.74 | F20: 7740 | G20: Sorghum-RM | H20: 1000000037 | I20: Mohd Karamallah | J20: 4500000567 | L20: Five Stars Sifter | M20: 1569.98 | N20: 15461 | O20: 160
A21: 46063 | B21: Five Stars Sifter | C21: 293 | D21: 80 | E21: =Table5[[#This Row],[Weight KG]]/1000 -> 7.76 | F21: 7760 | G21: Sorghum-RM | H21: 1000000037 | I21: Mohd Karamallah | J21: 4500000567 | L21: Sorghum-RM
A22: 46063 | B22: Five Stars Sifter | C22: 15094 | D22: 80 | E22: =Table5[[#This Row],[Weight KG]]/1000 -> 7.86 | F22: 7860 | G22: Sorghum-RM | H22: 1000000037 | I22: Mohd Karamallah | J22: 4500000567 | L22: 4500000567 | M22: 1569.98 | N22: 15461 | O22: 160
A23: 46063 | B23: Five Stars Sifter | C23: 1080 | D23: 80 | E23: =Table5[[#This Row],[Weight KG]]/1000 -> 8 | F23: 8000 | G23: Sorghum-RM | H23: 1000000037 | I23: Mohd Karamallah | J23: 4500000567 | L23: Feb
A24: 46063 | B24: Five Stars Sifter | C24: 764 | D24: 80 | E24: =Table5[[#This Row],[Weight KG]]/1000 -> 8 | F24: 8000 | G24: Sorghum-RM | H24: 1000000037 | I24: Mohd Karamallah | J24: 4500000567 | L24: 10-Feb | M24: 222.02 | N24: 2220 | O24: 27
A25: 46063 | B25: Five Stars Sifter | C25: 91 | D25: 80 | E25: =Table5[[#This Row],[Weight KG]]/1000 -> 7.94 | F25: 7940 | G25: Sorghum-RM | H25: 1000000037 | I25: Mohd Karamallah | J25: 4500000567 | L25: 11-Feb | M25: 301.44 | N25: 3000 | O25: 37
A26: 46063 | B26: Five Stars Sifter | C26: 1717 | D26: 80 | E26: =Table5[[#This Row],[Weight KG]]/1000 -> 8.04 | F26: 8040 | G26: Sorghum-RM | H26: 1000000037 | I26: Mohd Karamallah | J26: 4500000567 | L26: 12-Feb | M26: 405.54 | N26: 4000 | O26: 46
A27: 46063 | B27: Five Stars Sifter | C27: 737 | D27: 80 | E27: =Table5[[#This Row],[Weight KG]]/1000 -> 8.02 | F27: 8020 | G27: Sorghum-RM | H27: 1000000037 | I27: Mohd Karamallah | J27: 4500000567 | L27: 14-Feb | M27: 271.54 | N27: 2641 | O27: 22
A28: 46063 | B28: Five Stars Sifter | C28: 915 | D28: 80 | E28: =Table5[[#This Row],[Weight KG]]/1000 -> 8.06 | F28: 8060 | G28: Sorghum-RM | H28: 1000000037 | I28: Mohd Karamallah | J28: 4500000567 | L28: 15-Feb | M28: 269.12 | N28: 2620 | O28: 25
A29: 46063 | B29: Five Stars Sifter | C29: 573 | D29: 80 | E29: =Table5[[#This Row],[Weight KG]]/1000 -> 8.06 | F29: 8060 | G29: Sorghum-RM | H29: 1000000037 | I29: Mohd Karamallah | J29: 4500000567 | L29: 16-Feb | M29: 100.32 | N29: 980 | O29: 3
A30: 46063 | B30: Five Stars Sifter | C30: 2226 | D30: 80 | E30: =Table5[[#This Row],[Weight KG]]/1000 -> 8 | F30: 8000 | G30: Sorghum-RM | H30: 1000000037 | I30: Mohd Karamallah | J30: 4500000567 | L30: Grand Total | M30: 11570.59 | N30: 15461 | O30: 160
A31: 46063 | B31: Five Stars Sifter | C31: 263 | D31: 80 | E31: =Table5[[#This Row],[Weight KG]]/1000 -> 8.04 | F31: 8040 | G31: Sorghum-RM | H31: 1000000037 | I31: Mohd Karamallah | J31: 4500000567
A32: 46063 | B32: Five Stars Sifter | C32: 42209 | D32: 80 | E32: =Table5[[#This Row],[Weight KG]]/1000 -> 8.1 | F32: 8100 | G32: Sorghum-RM | H32: 1000000037 | I32: Mohd Karamallah | J32: 4500000567
A33: 46063 | B33: Five Stars Sifter | C33: 16429 | D33: 82 | E33: =Table5[[#This Row],[Weight KG]]/1000 -> 8.28 | F33: 8280 | G33: Sorghum-RM | H33: 1000000037 | I33: Mohd Karamallah | J33: 4500000567
A34: 46063 | B34: Five Stars Sifter | C34: 69 | D34: 138 | E34: =Table5[[#This Row],[Weight KG]]/1000 -> 14.56 | F34: 14560 | G34: Sorghum-RM | H34: 1000000037 | I34: Mohd Karamallah | J34: 4500000567
A35: 46064 | B35: Five Stars Sifter | C35: 70579 | D35: 85 | E35: =Table5[[#This Row],[Weight KG]]/1000 -> 8.28 | F35: 8280 | G35: Sorghum-RM | H35: 1000000037 | I35: Mohd Karamallah | J35: 4500000567
A36: 46064 | B36: Five Stars Sifter | C36: 59757 | D36: 80 | E36: =Table5[[#This Row],[Weight KG]]/1000 -> 7.98 | F36: 7980 | G36: Sorghum-RM | H36: 1000000037 | I36: Mohd Karamallah | J36: 4500000567
A37: 46064 | B37: Five Stars Sifter | C37: 42209 | D37: 85 | E37: =Table5[[#This Row],[Weight KG]]/1000 -> 8.3 | F37: 8300 | G37: Sorghum-RM | H37: 1000000037 | I37: Mohd Karamallah | J37: 4500000567
A38: 46064 | B38: Five Stars Sifter | C38: 9373 | D38: 80 | E38: =Table5[[#This Row],[Weight KG]]/1000 -> 8 | F38: 8000 | G38: Sorghum-RM | H38: 1000000037 | I38: Mohd Karamallah | J38: 4500000567
A39: 46064 | B39: Five Stars Sifter | C39: 605 | D39: 80 | E39: =Table5[[#This Row],[Weight KG]]/1000 -> 8.06 | F39: 8060 | G39: Sorghum-RM | H39: 1000000037 | I39: Mohd Karamallah | J39: 4500000567
A40: 46064 | B40: Five Stars Sifter | C40: 938 | D40: 80 | E40: =Table5[[#This Row],[Weight KG]]/1000 -> 8.1 | F40: 8100 | G40: Sorghum-RM | H40: 1000000037 | I40: Mohd Karamallah | J40: 4500000567
...

Sheet Pigeon Peas
A1: Date | B1: Receiving Location | C1: Truck No. | D1: Bags | E1: Gross Weight MT | F1: Gross Weight KG | G1: Net Weight KG | H1: Net Weight MT | I1: Commodity | J1: Commodity Code | K1: Supplier Name | L1: PO# | N1: Summary
A2: 46116 | B2: PZU WH-A013 | C2: 14663 | D2: 1049 | E2: 51.76 | F2: =Table6[[#This Row],[Gross Weight MT]]*1000 -> 51760 | G2: =Table6[[#This Row],[Gross Weight KG]]-(Table6[[#This Row],[ Bags]]*0.1) -> 51655.1 | H2: =Table6[[#This Row],[Net Weight KG]]/1000 -> 51.6551 | I2: Pigeon Peas FG | J2: 4000000059 | K2: Abdallah Abdealziz | L2: 4500001484 | N2: Receiving Location | O2: Weight MT | P2: Bags No. | Q2: Truck No.
A3: 46116 | B3: PZU WH-A013 | C3: 9158 | D3: 1050 | E3: 52.5 | F3: =Table6[[#This Row],[Gross Weight MT]]*1000 -> 52500 | G3: =Table6[[#This Row],[Gross Weight KG]]-(Table6[[#This Row],[ Bags]]*0.1) -> 52395 | H3: =Table6[[#This Row],[Net Weight KG]]/1000 -> 52.395 | I3: Pigeon Peas FG | J3: 4000000059 | K3: Abdallah Abdealziz | L3: 4500001484 | N3: PZU WH-A013 | O3: 3913.32 | P3: 78492 | Q3: 78
A4: 46118 | B4: PZU WH-A013 | C4: 34379 | D4: 1050 | E4: 52.56 | F4: =Table6[[#This Row],[Gross Weight MT]]*1000 -> 52560 | G4: =Table6[[#This Row],[Gross Weight KG]]-(Table6[[#This Row],[ Bags]]*0.1) -> 52455 | H4: =Table6[[#This Row],[Net Weight KG]]/1000 -> 52.455 | I4: Pigeon Peas FG | J4: 4000000059 | K4: Abdallah Abdealziz | L4: 4500001484 | N4: 4000000059 | O4: 3913.32 | P4: 78492 | Q4: 78
A5: 46118 | B5: PZU WH-A013 | C5: 33083 | D5: 1050 | E5: 52.7 | F5: =Table6[[#This Row],[Gross Weight MT]]*1000 -> 52700 | G5: =Table6[[#This Row],[Gross Weight KG]]-(Table6[[#This Row],[ Bags]]*0.1) -> 52595 | H5: =Table6[[#This Row],[Net Weight KG]]/1000 -> 52.595 | I5: Pigeon Peas FG | J5: 4000000059 | K5: Abdallah Abdealziz | L5: 4500001484 | N5: Abdallah Abdealziz | O5: 2815.62 | P5: 56492 | Q5: 56
A6: 46118 | B6: PZU WH-A013 | C6: 23825 | D6: 1050 | E6: 52.52 | F6: =Table6[[#This Row],[Gross Weight MT]]*1000 -> 52520 | G6: =Table6[[#This Row],[Gross Weight KG]]-(Table6[[#This Row],[ Bags]]*0.1) -> 52415 | H6: =Table6[[#This Row],[Net Weight KG]]/1000 -> 52.415 | I6: Pigeon Peas FG | J6: 4000000059 | K6: Abdallah Abdealziz | L6: 4500001484 | N6: PO#4500001484 | O6: 724.46 | P6: 14496 | Q6: 14
A7: 46121 | B7: PZU WH-A013 | C7: 23831 | D7: 1047 | E7: 52.1 | F7: =Table6[[#This Row],[Gross Weight MT]]*1000 -> 52100 | G7: =Table6[[#This Row],[Gross Weight KG]]-(Table6[[#This Row],[ Bags]]*0.1) -> 51995.3 | H7: =Table6[[#This Row],[Net Weight KG]]/1000 -> 51.9953 | I7: Pigeon Peas FG | J7: 4000000059 | K7: Abdallah Abdealziz | L7: 4500001484 | N7: PO#4500001654 | O7: 1540.08 | P7: 31000 | Q7: 31
A8: 46121 | B8: PZU WH-A013 | C8: 18118 | D8: 1000 | E8: 49.68 | F8: =Table6[[#This Row],[Gross Weight MT]]*1000 -> 49680 | G8: =Table6[[#This Row],[Gross Weight KG]]-(Table6[[#This Row],[ Bags]]*0.1) -> 49580 | H8: =Table6[[#This Row],[Net Weight KG]]/1000 -> 49.58 | I8: Pigeon Peas FG | J8: 4000000059 | K8: Abdallah Abdealziz | L8: 4500001654 | N8: PO#4500005939 | O8: 551.08 | P8: 10996 | Q8: 11
A9: 46121 | B9: PZU WH-A013 | C9: 17575 | D9: 1000 | E9: 49.8 | F9: =Table6[[#This Row],[Gross Weight MT]]*1000 -> 49800 | G9: =Table6[[#This Row],[Gross Weight KG]]-(Table6[[#This Row],[ Bags]]*0.1) -> 49700 | H9: =Table6[[#This Row],[Net Weight KG]]/1000 -> 49.7 | I9: Pigeon Peas FG | J9: 4000000059 | K9: Abdallah Abdealziz | L9: 4500001654 | N9: Magdi Gournas | O9: 898 | P9: 18000 | Q9: 18
A10: 46122 | B10: PZU WH-A013 | C10: 14537 | D10: 1000 | E10: 50.02 | F10: =Table6[[#This Row],[Gross Weight MT]]*1000 -> 50020 | G10: =Table6[[#This Row],[Gross Weight KG]]-(Table6[[#This Row],[ Bags]]*0.1) -> 49920 | H10: =Table6[[#This Row],[Net Weight KG]]/1000 -> 49.92 | I10: Pigeon Peas FG | J10: 4000000059 | K10: Abdallah Abdealziz | L10: 4500001654 | N10: PO#4500001652 | O10: 898 | P10: 18000 | Q10: 18
A11: 46122 | B11: PZU WH-A013 | C11: 35808 | D11: 1000 | E11: 49.92 | F11: =Table6[[#This Row],[Gross Weight MT]]*1000 -> 49920 | G11: =Table6[[#This Row],[Gross Weight KG]]-(Table6[[#This Row],[ Bags]]*0.1) -> 49820 | H11: =Table6[[#This Row],[Net Weight KG]]/1000 -> 49.82 | I11: Pigeon Peas FG | J11: 4000000059 | K11: Abdallah Abdealziz | L11: 4500001654 | N11: Mohd Karmallah | O11: 199.7 | P11: 4000 | Q11: 4
A12: 46122 | B12: PZU WH-A013 | C12: 23317 | D12: 1000 | E12: 49.62 | F12: =Table6[[#This Row],[Gross Weight MT]]*1000 -> 49620 | G12: =Table6[[#This Row],[Gross Weight KG]]-(Table6[[#This Row],[ Bags]]*0.1) -> 49520 | H12: =Table6[[#This Row],[Net Weight KG]]/1000 -> 49.52 | I12: Pigeon Peas FG | J12: 4000000059 | K12: Abdallah Abdealziz | L12: 4500001654 | N12: PO#4500002146 | O12: 199.7 | P12: 4000 | Q12: 4
A13: 46124 | B13: PZU WH-A013 | C13: 21385 | D13: 1050 | E13: 52.4 | F13: =Table6[[#This Row],[Gross Weight MT]]*1000 -> 52400 | G13: =Table6[[#This Row],[Gross Weight KG]]-(Table6[[#This Row],[ Bags]]*0.1) -> 52295 | H13: =Table6[[#This Row],[Net Weight KG]]/1000 -> 52.295 | I13: Pigeon Peas FG | J13: 4000000059 | K13: Abdallah Abdealziz | L13: 4500001484 | N13: NH-Agent WH | O13: 315 | P13: 6300 | Q13: 6
A14: 46130 | B14: PZU WH-A013 | C14: 10335 | D14: 1000 | E14: 49.72 | F14: =Table6[[#This Row],[Gross Weight MT]]*1000 -> 49720 | G14: =Table6[[#This Row],[Gross Weight KG]]-(Table6[[#This Row],[ Bags]]*0.1) -> 49620 | H14: =Table6[[#This Row],[Net Weight KG]]/1000 -> 49.62 | I14: Pigeon Peas FG | J14: 4000000059 | K14: Magdi Gournas | L14: 4500001652 | N14: 1000000035 | O14: 315 | P14: 6300 | Q14: 6
A15: 46132 | B15: PZU WH-A013 | C15: 452 | D15: 1050 | E15: 52.52 | F15: =Table6[[#This Row],[Gross Weight MT]]*1000 -> 52520 | G15: =Table6[[#This Row],[Gross Weight KG]]-(Table6[[#This Row],[ Bags]]*0.1) -> 52415 | H15: =Table6[[#This Row],[Net Weight KG]]/1000 -> 52.415 | I15: Pigeon Peas FG | J15: 4000000059 | K15: Abdallah Abdealziz | L15: 4500001484 | N15: Magdi Gournas | O15: 315 | P15: 6300 | Q15: 6
A16: 46132 | B16: PZU WH-A013 | C16: 13825 | D16: 1000 | E16: 49.16 | F16: =Table6[[#This Row],[Gross Weight MT]]*1000 -> 49160 | G16: =Table6[[#This Row],[Gross Weight KG]]-(Table6[[#This Row],[ Bags]]*0.1) -> 49060 | H16: =Table6[[#This Row],[Net Weight KG]]/1000 -> 49.06 | I16: Pigeon Peas FG | J16: 4000000059 | K16: Abdallah Abdealziz | L16: 4500001654 | N16: PO#4500005740 | O16: 315 | P16: 6300 | Q16: 6
A17: 46132 | B17: PZU WH-A013 | C17: 14541 | D17: 1000 | E17: 49.46 | F17: =Table6[[#This Row],[Gross Weight MT]]*1000 -> 49460 | G17: =Table6[[#This Row],[Gross Weight KG]]-(Table6[[#This Row],[ Bags]]*0.1) -> 49360 | H17: =Table6[[#This Row],[Net Weight KG]]/1000 -> 49.36 | I17: Pigeon Peas FG | J17: 4000000059 | K17: Abdallah Abdealziz | L17: 4500001654 | N17: Grand Total | O17: 4228.32 | P17: 84792 | Q17: 84
A18: 46132 | B18: PZU WH-A013 | C18: 14543 | D18: 1000 | E18: 49.48 | F18: =Table6[[#This Row],[Gross Weight MT]]*1000 -> 49480 | G18: =Table6[[#This Row],[Gross Weight KG]]-(Table6[[#This Row],[ Bags]]*0.1) -> 49380 | H18: =Table6[[#This Row],[Net Weight KG]]/1000 -> 49.38 | I18: Pigeon Peas FG | J18: 4000000059 | K18: Abdallah Abdealziz | L18: 4500001654
A19: 46132 | B19: PZU WH-A013 | C19: 9511 | D19: 1000 | E19: 49.88 | F19: =Table6[[#This Row],[Gross Weight MT]]*1000 -> 49880 | G19: =Table6[[#This Row],[Gross Weight KG]]-(Table6[[#This Row],[ Bags]]*0.1) -> 49780 | H19: =Table6[[#This Row],[Net Weight KG]]/1000 -> 49.78 | I19: Pigeon Peas FG | J19: 4000000059 | K19: Mohd Karmallah | L19: 4500002146
A20: 46132 | B20: PZU WH-A013 | C20: 100109 | D20: 1000 | E20: 50 | F20: =Table6[[#This Row],[Gross Weight MT]]*1000 -> 50000 | G20: =Table6[[#This Row],[Gross Weight KG]]-(Table6[[#This Row],[ Bags]]*0.1) -> 49900 | H20: =Table6[[#This Row],[Net Weight KG]]/1000 -> 49.9 | I20: Pigeon Peas FG | J20: 4000000059 | K20: Mohd Karmallah | L20: 4500002146
A21: 46133 | B21: PZU WH-A013 | C21: 17581 | D21: 1000 | E21: 49.48 | F21: =Table6[[#This Row],[Gross Weight MT]]*1000 -> 49480 | G21: =Table6[[#This Row],[Gross Weight KG]]-(Table6[[#This Row],[ Bags]]*0.1) -> 49380 | H21: =Table6[[#This Row],[Net Weight KG]]/1000 -> 49.38 | I21: Pigeon Peas FG | J21: 4000000059 | K21: Abdallah Abdealziz | L21: 4500001654
A22: 46133 | B22: PZU WH-A013 | C22: 9302 | D22: 1000 | E22: 50.24 | F22: =Table6[[#This Row],[Gross Weight MT]]*1000 -> 50240 | G22: =Table6[[#This Row],[Gross Weight KG]]-(Table6[[#This Row],[ Bags]]*0.1) -> 50140 | H22: =Table6[[#This Row],[Net Weight KG]]/1000 -> 50.14 | I22: Pigeon Peas FG | J22: 4000000059 | K22: Magdi Gournas | L22: 4500001652
A23: 46133 | B23: PZU WH-A013 | C23: 17577 | D23: 1000 | E23: 49.74 | F23: =Table6[[#This Row],[Gross Weight MT]]*1000 -> 49740 | G23: =Table6[[#This Row],[Gross Weight KG]]-(Table6[[#This Row],[ Bags]]*0.1) -> 49640 | H23: =Table6[[#This Row],[Net Weight KG]]/1000 -> 49.64 | I23: Pigeon Peas FG | J23: 4000000059 | K23: Abdallah Abdealziz | L23: 4500001654
A24: 46134 | B24: PZU WH-A013 | C24: 25824 | D24: 1053 | E24: 52.96 | F24: =Table6[[#This Row],[Gross Weight MT]]*1000 -> 52960 | G24: =Table6[[#This Row],[Gross Weight KG]]-(Table6[[#This Row],[ Bags]]*0.1) -> 52854.7 | H24: =Table6[[#This Row],[Net Weight KG]]/1000 -> 52.8547 | I24: Pigeon Peas FG | J24: 4000000059 | K24: Abdallah Abdealziz | L24: 4500001484
A25: 46134 | B25: PZU WH-A013 | C25: 36280 | D25: 1000 | E25: 49.82 | F25: =Table6[[#This Row],[Gross Weight MT]]*1000 -> 49820 | G25: =Table6[[#This Row],[Gross Weight KG]]-(Table6[[#This Row],[ Bags]]*0.1) -> 49720 | H25: =Table6[[#This Row],[Net Weight KG]]/1000 -> 49.72 | I25: Pigeon Peas FG | J25: 4000000059 | K25: Magdi Gournas | L25: 4500001652
A26: 46134 | B26: PZU WH-A013 | C26: 11245 | D26: 1000 | E26: 49.82 | F26: =Table6[[#This Row],[Gross Weight MT]]*1000 -> 49820 | G26: =Table6[[#This Row],[Gross Weight KG]]-(Table6[[#This Row],[ Bags]]*0.1) -> 49720 | H26: =Table6[[#This Row],[Net Weight KG]]/1000 -> 49.72 | I26: Pigeon Peas FG | J26: 4000000059 | K26: Mohd Karmallah | L26: 4500002146
A27: 46135 | B27: PZU WH-A013 | C27: 35804 | D27: 1000 | E27: 50 | F27: =Table6[[#This Row],[Gross Weight MT]]*1000 -> 50000 | G27: =Table6[[#This Row],[Gross Weight KG]]-(Table6[[#This Row],[ Bags]]*0.1) -> 49900 | H27: =Table6[[#This Row],[Net Weight KG]]/1000 -> 49.9 | I27: Pigeon Peas FG | J27: 4000000059 | K27: Mohd Karmallah | L27: 4500002146
A28: 46135 | B28: PZU WH-A013 | C28: 18216 | D28: 1000 | E28: 48.78 | F28: =Table6[[#This Row],[Gross Weight MT]]*1000 -> 48780 | G28: =Table6[[#This Row],[Gross Weight KG]]-(Table6[[#This Row],[ Bags]]*0.1) -> 48680 | H28: =Table6[[#This Row],[Net Weight KG]]/1000 -> 48.68 | I28: Pigeon Peas FG | J28: 4000000059 | K28: Magdi Gournas | L28: 4500001652
A29: 46135 | B29: PZU WH-A013 | C29: 14661 | D29: 1050 | E29: 52.4 | F29: =Table6[[#This Row],[Gross Weight MT]]*1000 -> 52400 | G29: =Table6[[#This Row],[Gross Weight KG]]-(Table6[[#This Row],[ Bags]]*0.1) -> 52295 | H29: =Table6[[#This Row],[Net Weight KG]]/1000 -> 52.295 | I29: Pigeon Peas FG | J29: 4000000059 | K29: Abdallah Abdealziz | L29: 4500001484
... A85: 46231 | B85: PZU WH-A013 | C85: 14662 | D85: 1000 | E85: 49.9 | F85: =Table6[[#This Row],[Gross Weight MT]]*1000 -> 49900 | G85: =Table6[[#This Row],[Gross Weight KG]]-(Table6[[#This Row],[ Bags]]*0.1) -> 49800 | H85: =Table6[[#This Row],[Net Weight KG]]/1000 -> 49.8 | I85: Pigeon Peas FG | J85: 4000000059 | K85: Abdallah Abdealziz | L85: 4500005939

Sheet WSNG
A1: Date | B1: Receiving Location | C1: Truck No. | D1: Jute Bags | E1: BP Bags | F1: SP Bags | G1: Weight KG | H1: Weight MT | I1: Commodity Code | J1: Supplier Name | K1: PO# | L1: Commodity | N1: Summary
A2: 46138 | B2: Balaji Sifter | C2: 33088 | D2: 31 | E2: 519 | G2: 49080 | H2: =Table7[[#This Row],[Weight KG]]/1000 -> 49.08 | I2: 1000000041 | J2: Abdallah Abdealziz | K2: 4500002362 | L2: WSNG-Eastern | N2: Receiving Location | O2: Weight MT | P2: Jute Bags | Q2: BP Bags | R2: SP Bags | S2: Truck No.
A3: 46138 | B3: Balaji Sifter | C3: 33079 | D3: 60 | E3: 490 | G3: 48940 | H3: =Table7[[#This Row],[Weight KG]]/1000 -> 48.94 | I3: 1000000041 | J3: Abdallah Abdealziz | K3: 4500002362 | L3: WSNG-Eastern | N3: Balaji Sifter | O3: 333.84 | P3: 111 | Q3: 1431 | R3: 3986 | S3: 7
A4: 46138 | B4: Balaji Sifter | C4: 33085 | D4: 20 | E4: 420 | F4: 165 | G4: 46920 | H4: =Table7[[#This Row],[Weight KG]]/1000 -> 46.92 | I4: 1000000041 | J4: Abdallah Abdealziz | K4: 4500002362 | L4: WSNG-Eastern | N4: Abdallah Abdealziz | O4: 333.84 | P4: 111 | Q4: 1431 | R4: 3986 | S4: 7
A5: 46141 | B5: Balaji Sifter | C5: 34015 | F5: 1027 | G5: 48660 | H5: =Table7[[#This Row],[Weight KG]]/1000 -> 48.66 | I5: 1000000041 | J5: Abdallah Abdealziz | K5: 4500002362 | L5: WSNG-Eastern | N5: PO#4500002362 | O5: 333.84 | P5: 111 | Q5: 1431 | R5: 3986 | S5: 7
A6: 46145 | B6: Balaji Sifter | C6: 32441 | F6: 951 | G6: 46900 | H6: =Table7[[#This Row],[Weight KG]]/1000 -> 46.9 | I6: 1000000041 | J6: Abdallah Abdealziz | K6: 4500002362 | L6: WSNG-Eastern | N6: Grand Total | O6: 333.84 | P6: 111 | Q6: 1431 | R6: 3986 | S6: 7
A7: 46145 | B7: Balaji Sifter | C7: 29190 | E7: 2 | F7: 892 | G7: 47960 | H7: =Table7[[#This Row],[Weight KG]]/1000 -> 47.96 | I7: 1000000041 | J7: Abdallah Abdealziz | K7: 4500002362 | L7: WSNG-Eastern
A8: 46145 | B8: Balaji Sifter | C8: 274922 | F8: 951 | G8: 45380 | H8: =Table7[[#This Row],[Weight KG]]/1000 -> 45.38 | I8: 1000000041 | J8: Abdallah Abdealziz | K8: 4500002362 | L8: WSNG-Eastern

Sheet Gum Arabic
A1: Date | B1: Receiving Location | C1: Truck No. | D1: Bags No. | E1: Weight KG | F1: Weight MT | G1: Commodity Code | H1: Supplier Name | I1: PO# | J1: Commodity | L1: Summary
A2: 46208 | B2: Baghier WH | C2: 23561 | D2: 856 | E2: 61250 | F2: =Table8[[#This Row],[Weight KG]]/1000 -> 61.25 | G2: 1000000033 | H2: Abdallah Abdealziz | I2: 4500006403 | J2: Gum Arabic Talha-RM | L2: Row Labels | M2: Weight MT | N2: Bags No. | O2: Truck No.
A3: 46209 | B3: Baghier WH | C3: 80162 | D3: 875 | E3: 63890 | F3: =Table8[[#This Row],[Weight KG]]/1000 -> 63.89 | G3: 1000000033 | H3: Abdallah Abdealziz | I3: 4500006403 | J3: Gum Arabic Talha-RM | L3: Baghier WH | M3: 245.247 | N3: 3420 | O3: 4
A4: 46209 | B4: Baghier WH | C4: 8478 | D4: 823 | E4: 56790 | F4: =Table8[[#This Row],[Weight KG]]/1000 -> 56.79 | G4: 1000000033 | H4: Abdallah Abdealziz | I4: 4500006403 | J4: Gum Arabic Talha-RM | L4: PO#4500006403 | M4: 245.247 | N4: 3420 | O4: 4
A5: 46210 | B5: Baghier WH | C5: 7595 | D5: 866 | E5: 63317 | F5: =Table8[[#This Row],[Weight KG]]/1000 -> 63.317 | G5: 1000000033 | H5: Abdallah Abdealziz | I5: 4500006403 | J5: Gum Arabic Talha-RM | L5: Grand Total | M5: 245.247 | N5: 3420 | O5: 4

Sheet PO#
A1: # | B1: PO# | C1: Commodity | D1: Supplier Name | E1: Goods Source | F1: Agreed Qty | G1: Unit of purchase | H1: Sifter Name | I1: Sifter Code | J1: Delivery | K1: Status | L1: Remark
A2: 1 | B2: 1763 | C2: Gadarif White Sesame | D2: Mohamed Karmalla -Fuknab Agri. | E2: Gadarif | F2: Collection | G2: MT | H2: Gadarif Warehouse | I2: AG | J2: PZU | K2: Closed
A3: 2 | B3: 1765 | C3: Non Gadarif Sesame | D3: Abdallah Abdelaziz | E3: Sennar | F3: Collection | G3: MT | H3: Not Available yet | J3: PZU | K3: Cancelled
A4: 3 | B4: 4500000001 | C4: Sorghum Raw | D4: Mohamed Karmalla -Fuknab Agri. | E4: Gadarif | F4: 5000 | G4: MT | H4: Concrete Silo SF | I4: SGCO | J4: Gadarif | K4: Closed
A5: 4 | B5: 4500000293 | C5: Sorghum Raw | D5: Mohamed Karmalla -Fuknab Agri. | E5: Gadarif | F5: 2500 | G5: MT | H5: Concrete Silo SF | I5: SGCO | J5: Gadarif | K5: Closed
A6: 5 | B6: 4500000294 | C6: Sorghum Finished | D6: Mohamed Karmalla -Fuknab Agri. | E6: Gadarif | F6: 480 | G6: MT | H6: Concrete Silo SF | I6: SGCO | J6: Gadarif | K6: Closed
C7: Sorghum Raw | F7: 2020 | H7: Concrete Silo SF | I7: SGCO | J7: Gadarif | K7: Closed
A8: 6 | B8: 4500000319 | C8: Pigeon Peas Raw | D8: Magdi Gurnas | E8: New Halfa | F8: 170 | G8: MT | H8: Not Available yet | J8: New Halfa | K8: On Going
A9: 7 | B9: 4500000384 | C9: Sesame White Gadarif Raw | D9: Mohamed Karmalla -Fuknab Agri. | E9: Gadarif | F9: 1000 | G9: MT | H9: KaramallahAbass | I9: GD08 | J9: Gadarif | K9: Closed
A10: 8 | B10: 4500000567 | C10: Sorghum Raw | D10: Mohamed Karmalla -Fuknab Agri. | E10: Gadarif | F10: 2100 | G10: MT | H10: Five Star Sifter | I10: SGFI | J10: Gadarif | K10: Closed
A11: 9 | B11: 4500001484 | C11: Pigeon Peas Finished | D11: Abdalla Abdelaziz | E11: Almnaqil | F11: 15000 | G11: Bags | H11: A13 Warehouse | I11: A013 | J11: PZU | K11: On Going
A12: 10 | B12: 4500001491 | C12: Sesame White Gadarif Raw | D12: Mohamed Karmalla -Fuknab Agri. | E12: Gadarif | F12: 319 | G12: MT | H12: KaramallahAbass | I12: GD08 | J12: Gadarif | K12: Closed
A13: 11 | B13: 4500001652 | C13: Pigeon Peas Finished | D13: Magdi Gurnas | E13: New Halfa | F13: 10400 | G13: Bags | H13: A13 Warehouse | I13: A013 | J13: PZU | K13: On Going
A14: 12 | B14: 4500001654 | C14: Pigeon Peas Finished | D14: Abdallah Abdelaziz | E14: New Halfa | F14: 12000 | G14: Bags | H14: A13 Warehouse | I14: A013 | J14: PZU | K14: On Going
A15: 13 | B15: 4500001655 | C15: Sesame White Gadarif Raw | D15: Mohamed Karmalla -Fuknab Agri. | E15: Gadarif | F15: 340 | G15: MT | H15: Balaji 1 SF PZU | I15: SPB1 | J15: PZU | K15: Closed
A16: 14 | B16: 4500002146 | C16: Pigeon Peas Finished | D16: Mohamed Karmalla -Fuknab Agri. | E16: Madani | F16: 200 | G16: MT | H16: A13 Warehouse | I16: A013 | J16: PZU | K16: Closed
A17: 15 | B17: 4500002362 | C17: Non Gadarif Sesame | D17: Abdallah Abdelaziz | E17: Sennar | F17: 315 | G17: MT | H17: Balaji 1 SF PZU | I17: SPB1 | J17: PZU | K17: On Going
A18: 16 | B18: 4500005740 | C18: Pigeon Peas Raw | D18: Magdi Gurnas | E18: New Halfa | F18: 250.00 | G18: MT | J18: New Halfa | K18: On Going
A19: 17 | B19: 4500005939 | C19: Pigeon Peas Finished | D19: Abdallah Abdelaziz | E19: Almnaqil | F19: 20,000.00 | G19: Bags | H19: A13 Warehouse | I19: A013 | J19: PZU | K19: On Going
A20: 18 | B20: 4500006403 | C20: Gum Arabic talha raw | D20: Abdallah Abdelaziz | E20: Sennar | F20: 224.72 | G20: MT | J20: Albagier | K20: On Going

Sheet Codes
B3: 1000000037 | C3: Sorghum Raw
B4: 1000000040 | C4: GS
B5: 4000000232 | C5: Sorghum Finished
