Workbook
Name NativeTimeline_Date: #N/A
Name Slicer_Period_Type: #N/A
Name Slicer_Period_Type1: #N/A
Name Slicer_Status: #N/A
Name Slicer_Status1: #N/A
Name Slicer_Type: #N/A
Name Slicer_Type1: #N/A
Name Timeline_Date: #N/A

Sheet Sheet1

Sheet Sheet4
A7: Comansate value USD per year
A8: Comansate value SDG per year
A21: Comparing Claim Value By year VS compansate value

Sheet Sheet5
A3: Row Labels | B3: Sum of Compensation Value USD | C3: Sum of Claim Value USD | D3: Sum of % Compansation
A4: 2024 | B4: 1682.28 | C4: 3263.479 | D4: 0.51548669
A5: 2025 | B5: 6554.36 | C5: 26749.059 | D5: 0.24503142
A6: 2026 | B6: 0 | C6: 18596.826 | D6: 0
A7: Grand Total | B7: 8236.64 | C7: 48609.365 | D7: 0.16944554

Sheet Summary
A1: Date | B1: Season | C1: Month | D1: Year | E1: Case Number | F1: BL NO. | G1: WH | H1: Location | I1: Product | J1: Product Description | K1: Owner | L1: Initial Quantity | M1: Claim Quantity | N1: Adjusted Quantity | O1: NC number | P1: Torn QTY | Q1: loss | R1: Sound from Torn QTY | S1: Unit | T1: Cause of Loss | U1: Insurance Type | V1: Type | W1: Detailed Description | X1: Available documents | Y1: Unit Cost USD | Z1: Total Value USD | AA1: Unit Cost - SDG | AB1: Total Value SDG | AC1: STD Cost-SDG | AD1: STD Value-SDG | AE1: Compensation Value | AF1: Exchange Rate | AG1: Compensation Status | AH1: System Status | AI1: Follow Up Person | AJ1: Period Type | AK1: Report by | AL1: Remark | AM1: Claim Status | AN1: Status | AO1: Status Update | AP1: Claim Value SDG | AQ1: Claim Value USD | AR1: Compensation Value USD | AS1: Different | AT1: % of different | AU1: Remark of different | AV1: Remark
A2: 45603 | B2: S7 | C2: =TEXT(A2,"MMM") -> Nov | D2: =YEAR(A2) -> 2024 | E2: 1 | F2: 3100033205A | G2: XI | H2: PZU-Bond area | I2: LE0001 | J2: LENTIL TAT 20KG | L2: 0 | M2: =VLOOKUP(Table1[[#This Row],[BL NO.]],'BL NCs'!$E$3:$K$78,7,0) -> 0 | N2: 0 | O2: Zero QTY | P2: 0 | Q2: 0 | R2: =Table1[[#This Row],[Torn QTY]]-Table1[[#This Row],[loss]] -> 0 | S2: 20KG BAGS | T2: Import Container Damage/Short | U2: Marine Insurance | V2: Import | W2: Final inspection report, which confirms that there are no damaged bags as previously reported Container NO:FYCU7233921, BL NO:3100033205A | X2: CIS report | Y2: 0 | Z2: =Y2*M2 -> 0 | AA2: 0 | AB2: =AA2*M2 -> 0 | AC2: 0 | AD2: =AC2*M2 -> 0 | AE2: =AR2 -> 0 | AF2: 0 | AG2: No claim required (Zero loss) | AH2: N/A | AI2: Ajay/Limitz | AJ2: Post-War | AK2: Rawan | AM2: Accept | AN2: Close | AO2: No cargo damage | AQ2: =Z2 -> 0 | AR2: 0 | AS2: =AQ2-AR2 -> 0 | AT2: =(AR2/AQ2-1)*-1 -> #DIV/0! | AU2: No cargo damage
A3: 45603 | B3: S7 | C3: =TEXT(A3,"MMM") -> Nov | D3: =YEAR(A3) -> 2024 | E3: 2 | F3: XERNSAPSZU14324. | G3: XI | H3: PZU-Bond area | I3: RC0004 | J3: RICE LONG ELNGM 20K | L3: 215 | M3: =VLOOKUP(Table1[[#This Row],[BL NO.]],'BL NCs'!$E$3:$K$78,7,0) -> 215 | N3: 0 | O3: Not found | P3: 0 | Q3: 0 | R3: =Table1[[#This Row],[Torn QTY]]-Table1[[#This Row],[loss]] -> 0 | S3: 20KG BAGS | T3: Import Container Damage/Short | U3: Marine Insurance | V3: Import | W3: Shipment arrived Bond Area, container NO: JZPU1111481, BL XERNSAPSZU14324. The damage quantity of rice in 20kg bags is (215 bags 20KG) noted in wet and damage condition. We have received 50% of claim amount after the standard deduction (as per the policy) from insurance company. From insurance side they have made payment and closed their file, amount received is $1248. | X3: CIS report/Photo | Y3: 11.609302 | Z3: =M3*Y3 -> 2496 | AA3: 34000 | AB3: =AA3*M3 -> 7310000 | AC3: 30750 | AD3: =AC3*M3 -> 6611250 | AE3: =AR3 -> 1248 | AF3: 2372 | AG3: Compensated | AH3: Adjusted | AI3: Ajay/Shijil | AJ3: Post-War | AK3: Rawan | AM3: Accept | AN3: Close | AO3: Insurance compensation | AQ3: =2496 -> 2496 | AR3: 1248 | AS3: =AQ3-AR3 -> 1248 | AT3: =(AR3/AQ3-1)*-1 -> 0.5 | AU3: As Shijil Email, We have received 50% of claim amount after the standard deduction (as per the policy) from insurance company.
A4: 45630 | B4: S7 | C4: =TEXT(A4,"MMM") -> Dec | D4: =YEAR(A4) -> 2024 | E4: 3 | F4: 245672578 | G4: XI | H4: PZU-Bond area | I4: LE0001 | J4: LENTIL TAT 20KG | L4: 0 | M4: =VLOOKUP(Table1[[#This Row],[BL NO.]],'BL NCs'!$E$3:$K$78,7,0) -> 0 | N4: 0 | O4: Zero QTY | P4: 0 | Q4: 0 | R4: =Table1[[#This Row],[Torn QTY]]-Table1[[#This Row],[loss]] -> 0 | S4: 20KG BAGS | T4: Import Container Damage/Short | U4: Marine Insurance | V4: Import | W4: Final inspection report, which confirms that there are no damaged bags as previously reported Container NO: CAAU6382276 /BL 245672578 | X4: CIS report | Y4: 0 | Z4: =Y4*M4 -> 0 | AA4: 0 | AB4: =AA4*M4 -> 0 | AC4: 0 | AD4: =AC4*M4 -> 0 | AE4: =AR4 -> 0 | AF4: 0 | AG4: No claim required (Zero loss) | AH4: N/A | AI4: Ajay/Limitz | AJ4: Post-War | AK4: Rawan | AM4: Accept | AN4: Close | AO4: No cargo damage | AQ4: =Z4 -> 0 | AR4: 0 | AS4: =AQ4-AR4 -> 0 | AT4: =(AR4/AQ4-1)*-1 -> #DIV/0! | AU4: No cargo damage
A5: 45630 | B5: S7 | C5: =TEXT(A5,"MMM") -> Dec | D5: =YEAR(A5) -> 2024 | E5: 4 | F5: 245672856 | G5: XI | H5: PZU-Bond area | I5: LE0001 | J5: LENTIL TAT 20KG | L5: 0 | M5: =VLOOKUP(Table1[[#This Row],[BL NO.]],'BL NCs'!$E$3:$K$78,7,0) -> 0 | N5: 0 | O5: Zero QTY | P5: 0 | Q5: 0 | R5: =Table1[[#This Row],[Torn QTY]]-Table1[[#This Row],[loss]] -> 0 | S5: 20KG BAGS | T5: Import Container Damage/Short | U5: Marine Insurance | V5: Import | W5: Final inspection report, which confirms that there are no damaged bags as previously reported Container NO:MSKU0899606 /BL 245672856 | X5: CIS report | Y5: 0 | Z5: =Y5*M5 -> 0 | AA5: 0 | AB5: =AA5*M5 -> 0 | AC5: 0 | AD5: =AC5*M5 -> 0 | AE5: =AR5 -> 0 | AF5: 0 | AG5: No claim required (Zero loss) | AH5: N/A | AI5: Ajay/Limitz | AJ5: Post-War | AK5: Rawan | AM5: Accept | AN5: Close | AO5: No cargo damage | AQ5: =Z5 -> 0 | AR5: 0 | AS5: =AQ5-AR5 -> 0 | AT5: =(AR5/AQ5-1)*-1 -> #DIV/0! | AU5: No cargo damage
A6: 45630 | B6: S7 | C6: =TEXT(A6,"MMM") -> Dec | D6: =YEAR(A6) -> 2024 | E6: 4 | F6: 245672856 | G6: XI | H6: PZU-Bond area | I6: LE0001 | J6: LENTIL TAT 20KG | L6: 21 | M6: 21 | N6: 0 | O6: Not found | P6: 0 | Q6: 0 | R6: =Table1[[#This Row],[Torn QTY]]-Table1[[#This Row],[loss]] -> 0 | S6: 20KG BAGS | T6: Import Container Damage/Short | U6: Marine Insurance | V6: Import | W6: Shipment arrived Bond Area, Container NO: MVIU0022134 /BL 245672856-The damage quantity of rice in 20kg bags is (21 bags 20KG), having received 434,28 USD being the insurance claim amount. | X6: CIS report/LOP | Y6: 20.68 | Z6: =Y6*M6 -> 434.28 | AA6: =Y6*AF6 -> 48598 | AB6: =AA6*M6 -> 1020558 | AC6: 47408.368 | AD6: =AC6*M6 -> 995575.74 | AE6: =AR6 -> 434.28 | AF6: 2350 | AG6: Compensated | AH6: Adjusted | AI6: Ajay/Limitz | AJ6: Post-War | AK6: Rawan | AM6: Accept | AN6: Close | AO6: Insurance compensation | AQ6: 434.28 | AR6: 434.28 | AS6: =AQ6-AR6 -> 0 | AT6: =(AR6/AQ6-1)*-1 -> 0 | AU6: Insurance compensated
A7: 45636 | B7: S7 | C7: =TEXT(A7,"MMM") -> Dec | D7: =YEAR(A7) -> 2024 | E7: 5 | F7: XERNSAPSZU1462425 | G7: XI | H7: PZU-Bond area | I7: RC0004 | J7: RICE LONG ELNGM 20K | L7: 25 | M7: =VLOOKUP(Table1[[#This Row],[BL NO.]],'BL NCs'!$E$3:$K$78,7,0) -> 25 | N7: 0 | O7: Not found | P7: 0 | Q7: 0 | R7: =Table1[[#This Row],[Torn QTY]]-Table1[[#This Row],[loss]] -> 0 | S7: 20KG BAGS | T7: Import Container Damage/Short | U7: Marine Insurance | V7: Import | W7: Shipment arrived Bond Area, Container NO:TEMU4187019 /BL XERNSAPSZU1462425 (14 bags), XERNSAPSZU1472425(11 bags) Total (25 bags). The damage quantity of rice in 20kg bags is 25 bags 20KG), case reject There is 0.5% excess payable for each claim (in this case $1826.55). Claim Value of 25 bags is less than 0.5% excess value hence insurance company has closed the file. | X7: CIS report/LOP | Y7: 13.327962 | Z7: =Y7*M7 -> 333.19904 | AA7: 31320.71 | AB7: =AA7*M7 -> 783017.75 | AC7: 29520.555 | AD7: =AC7*M7 -> 738013.89 | AE7: =AR7 -> 0 | AF7: 2350 | AG7: Loss | AH7: Adjusted | AI7: Ajay/Shijil | AJ7: Post-War | AK7: Rawan | AM7: Accept | AN7: Close | AO7: Less than deductible | AQ7: =Z7 -> 333.19904 | AR7: 0 | AS7: =AQ7-AR7 -> 333.19904 | AT7: =(AR7/AQ7-1)*-1 -> 1 | AU7: Less than deductible (0.5%)
A8: 45682 | B8: S7 | C8: =TEXT(A8,"MMM") -> Jan | D8: =YEAR(A8) -> 2025 | E8: 6 | F8: 247070297 | G8: XI | H8: PZU | I8: LE0001 | J8: LENTIL TAT 20KG | L8: 45 | M8: =VLOOKUP(Table1[[#This Row],[BL NO.]],'BL NCs'!$E$3:$K$78,7,0) -> 45 | N8: 0 | O8: Short | P8: 0 | Q8: 0 | R8: =Table1[[#This Row],[Torn QTY]]-Table1[[#This Row],[loss]] -> 0 | S8: 20KG BAGS | T8: Import Container Damage/Short | U8: Marine Insurance | V8: Import | W8: 45 bags found shortage at container BL:247070297 - MAEU247070297 | X8: CIS report/LOP | Y8: 20.135917 | Z8: =Y8*M8 -> 906.11628 | AA8: 52000 | AB8: =AA8*M8 -> 2340000 | AC8: 48417.057 | AD8: =AC8*M8 -> 2178767.6 | AE8: =AR8 -> 0 | AF8: 2582.45 | AG8: Pending | AH8: Adjusted | AI8: Ajay/Limitz | AJ8: Post-War | AK8: Rawan | AM8: Pending | AN8: Pending | AO8: Case submitted/ Waiting Insurance feedback | AQ8: =Z8 -> 906.11628 | AR8: 0 | AS8: =AQ8-AR8 -> 906.11628 | AT8: =(AR8/AQ8-1)*-1 -> 1 | AU8: Waiting Feedback
A9: 45701 | B9: S7 | C9: =TEXT(A9,"MMM") -> Feb | D9: =YEAR(A9) -> 2025 | E9: 7 | F9: 248620904 | G9: XI | H9: PZU-Bond area | I9: LE0001 | J9: LENTIL TAT 20KG | L9: 54 | M9: =VLOOKUP(Table1[[#This Row],[BL NO.]],'BL NCs'!$E$3:$K$78,7,0) -> 54 | N9: 0 | O9: Short | P9: 0 | Q9: 0 | R9: =Table1[[#This Row],[Torn QTY]]-Table1[[#This Row],[loss]] -> 0 | S9: 20KG BAGS | T9: Import Container Damage/Short | U9: Marine Insurance | V9: Import | W9: 54 bags found shortage at container BL:248620904. Delivered DN and insurance compansate. | X9: CIS report/LOP | Y9: 20.02 | Z9: =Y9*M9 -> 1081.08 | AA9: 51700.649 | AB9: =AA9*M9 -> 2791835 | AC9: 52451.812 | AD9: =AC9*M9 -> 2832397.8 | AE9: =AR9 -> 1081.08 | AF9: 2582.45 | AG9: Compensated | AH9: Adjusted | AI9: Ajay/Limitz | AJ9: Post-War | AK9: Rawan | AM9: Accept | AN9: Close | AO9: Insurance compensation | AQ9: =Z9 -> 1081.08 | AR9: 1081.08 | AS9: =AQ9-AR9 -> 0 | AT9: =(AR9/AQ9-1)*-1 -> 0 | AU9: Insurance compensated
A10: 45703 | B10: S7 | C10: =TEXT(A10,"MMM") -> Feb | D10: =YEAR(A10) -> 2025 | E10: 8 | F10: 248619667 | G10: XI | H10: PZU-Bond area | I10: LE0001 | J10: LENTIL TAT 20KG | L10: 107 | M10: =VLOOKUP(Table1[[#This Row],[BL NO.]],'BL NCs'!$E$3:$K$78,7,0) -> 107 | N10: 0 | O10: Short | P10: 0 | Q10: 0 | R10: =Table1[[#This Row],[Torn QTY]]-Table1[[#This Row],[loss]] -> 0 | S10: 20KG BAGS | T10: Import Container Damage/Short | U10: Marine Insurance | V10: Import | W10: 107 bags found shortage at container BL:248619667. Delivered DN and insurance compansate. | X10: CIS report/LOP | Y10: 20.02 | Z10: =Y10*M10 -> 2142.14 | AA10: 51700.649 | AB10: =AA10*M10 -> 5531969.4 | AC10: 52451.812 | AD10: =AC10*M10 -> 5612343.9 | AE10: =AR10 -> 2142.14 | AF10: 2582.45 | AG10: Compensated | AH10: Adjusted | AI10: Ajay/Limitz | AJ10: Post-War | AK10: Rawan | AM10: Accept | AN10: Close | AO10: Insurance compensation | AQ10: =Z10 -> 2142.14 | AR10: 2142.14 | AS10: =AQ10-AR10 -> 0 | AT10: =(AR10/AQ10-1)*-1 -> 0 | AU10: Insurance compensated
A11: 45713 | B11: S7 | C11: =TEXT(A11,"MMM") -> Feb | D11: =YEAR(A11) -> 2025 | E11: 9 | F11: 248620255 | G11: XI | H11: PZU-Bond area | I11: LE0001 | J11: LENTIL TAT 20KG | L11: 55 | M11: =VLOOKUP(Table1[[#This Row],[BL NO.]],'BL NCs'!$E$3:$K$78,7,0) -> 55 | N11: 0 | O11: Short | P11: 0 | Q11: 0 | R11: =Table1[[#This Row],[Torn QTY]]-Table1[[#This Row],[loss]] -> 0 | S11: 20KG BAGS | T11: Import Container Damage/Short | U11: Marine Insurance | V11: Import | W11: 55 bags found shortage at container BL:248620255. Delivered DN and insurance compansate. | X11: CIS report/LOP | Y11: =Z11/M11 -> 20.02 | Z11: 1101.1 | AA11: 51700.649 | AB11: =AA11*M11 -> 2843535.7 | AC11: 52451.812 | AD11: =AC11*M11 -> 2884849.7 | AE11: =AR11 -> 1101.1 | AF11: 2582.45 | AG11: Compensated | AH11: Adjusted | AI11: Ajay/Limitz | AJ11: Post-War | AK11: Rawan | AM11: Accept | AN11: Close | AO11: Insurance compensation | AQ11: =Z11 -> 1101.1 | AR11: 1101.1 | AS11: =AQ11-AR11 -> 0 | AT11: =(AR11/AQ11-1)*-1 -> 0 | AU11: Insurance compensated
A12: 45714 | B12: S7 | C12: =TEXT(A12,"MMM") -> Feb | D12: =YEAR(A12) -> 2025 | E12: 10 | F12: 248621429 | G12: XI | H12: PZU-Bond area | I12: LE0001 | J12: LENTIL TAT 20KG | L12: 30 | M12: =VLOOKUP(Table1[[#This Row],[BL NO.]],'BL NCs'!$E$3:$K$78,7,0) -> 30 | N12: 0 | O12: Short | P12: 0 | Q12: 0 | R12: =Table1[[#This Row],[Torn QTY]]-Table1[[#This Row],[loss]] -> 0 | S12: 20KG BAGS | T12: Import Container Damage/Short | U12: Marine Insurance | V12: Import | W12: 30 bags found shortage at container BL:248621429. Delivered DN and insurance compansate. | X12: CIS report/LOP | Y12: =Z12/M12 -> 20 | Z12: 600 | AA12: =Y12*AF12 -> 51649 | AB12: =AA12*M12 -> 1549470 | AC12: 52451.812 | AD12: =AC12*M12 -> 1573554.4 | AE12: =AR12 -> 600 | AF12: 2582.45 | AG12: Compensated | AH12: Adjusted | AI12: Ajay/Limitz | AJ12: Post-War | AK12: Rawan | AM12: Accept | AN12: Close | AO12: Insurance compensation | AQ12: =Z12 -> 600 | AR12: 600 | AS12: =AQ12-AR12 -> 0 | AT12: =(AR12/AQ12-1)*-1 -> 0 | AU12: Insurance compensated
A13: 45722 | B13: S7 | C13: =TEXT(A13,"MMM") -> Mar | D13: =YEAR(A13) -> 2025 | E13: 11 | F13: 248622146 | G13: E2 | H13: PZU | I13: LE0001 | J13: LENTIL TAT 20KG | L13: 62 | M13: =VLOOKUP(Table1[[#This Row],[BL NO.]],'BL NCs'!$E$3:$K$78,7,0) -> 62 | O13: Short | P13: 0 | Q13: 0 | R13: =Table1[[#This Row],[Torn QTY]]-Table1[[#This Row],[loss]] -> 0 | S13: 20KG BAGS | T13: Import Container Damage/Short | U13: Marine Insurance | V13: Import | W13: 62 bags found shortage at container BL:248622146. Delivered DN and insurance compansate. | X13: CIS report/LOP | Y13: 20.02 | Z13: =Y13*M13 -> 1241.24 | AA13: =Y13*AF13 -> 51200.95 | AB13: =AA13*M13 -> 3174458.9 | AC13: 50018.235 | AD13: =AC13*M13 -> 3101130.6 | AE13: =AR13 -> 1241.24 | AF13: 2557.49 | AG13: Compensated | AH13: Adjusted | AI13: Ajay/Limitz | AJ13: Post-War | AK13: Rawan | AM13: Accept | AN13: Close | AO13: Insurance compensation | AQ13: =Z13 -> 1241.24 | AR13: 1241.24 | AS13: =AQ13-AR13 -> 0 | AT13: =(AR13/AQ13-1)*-1 -> 0 | AU13: Insurance compensated
A14: 45745 | B14: S7 | C14: =TEXT(A14,"MMM") -> Mar | D14: =YEAR(A14) -> 2025 | E14: 12 | F14: 248623021 | G14: E2 | H14: PZU | I14: LE0001 | J14: LENTIL TAT 20KG | L14: 54 | M14: =VLOOKUP(Table1[[#This Row],[BL NO.]],'BL NCs'!$E$3:$K$78,7,0) -> 54 | O14: Short | P14: 0 | Q14: 0 | R14: =Table1[[#This Row],[Torn QTY]]-Table1[[#This Row],[loss]] -> 0 | S14: 20KG BAGS | T14: Import Container Damage/Short | U14: Marine Insurance | V14: Import | W14: 54 bags found shortage at container BL:248623021. Short bag less than deductable .05% | X14: CIS report/LOP | Y14: 20.98 | Z14: 1132.92 | AA14: 53500 | AB14: 2889000 | AC14: 50018.235 | AD14: 2700984.7 | AE14: =AR14 -> 0 | AF14: 2550 | AG14: Loss | AH14: Adjusted | AI14: Ajay/Limitz | AJ14: Post-War | AK14: Rawan | AM14: Accept | AN14: Close | AO14: Less than deductible | AQ14: =Z14 -> 1132.92 | AR14: 0 | AS14: =AQ14-AR14 -> 1132.92 | AT14: =(AR14/AQ14-1)*-1 -> 1 | AU14: Less than deductible (0.5%)
A15: 45770 | B15: S7 | C15: =TEXT(A15,"MMM") -> Apr | D15: =YEAR(A15) -> 2025 | E15: 13 | F15: 248624161 | G15: XZ | H15: PZU | I15: LE0001 | J15: LENTIL TAT 20KG | L15: 28 | M15: =VLOOKUP(Table1[[#This Row],[BL NO.]],'BL NCs'!$E$3:$K$78,7,0) -> 28 | O15: Short | P15: 0 | Q15: 0 | R15: =Table1[[#This Row],[Torn QTY]]-Table1[[#This Row],[loss]] -> 0 | S15: 20KG BAGS | T15: Import Container Damage/Short | U15: Marine Insurance | V15: Import | W15: 28 bags found shortage at container BL:248624161 | X15: CIS report/LOP | Y15: 22.71 | Z15: =Y15*M15 -> 635.88 | AA15: 58000 | AB15: =AA15*M15 -> 1624000 | AC15: 50018.235 | AD15: =AC15*M15 -> 1400510.6 | AE15: =AR15 -> 0 | AF15: 2554.48 | AG15: Loss | AH15: Adjusted | AI15: Ajay/Limitz | AJ15: Post-War | AK15: Rawan | AM15: Accept | AN15: Close | AO15: Less than deductible | AQ15: =Z15 -> 635.88 | AR15: 0 | AS15: =AQ15-AR15 -> 635.88 | AT15: =(AR15/AQ15-1)*-1 -> 1 | AU15: Less than deductible (0.5%)
A16: 45770 | B16: S7 | C16: =TEXT(A16,"MMM") -> Apr | D16: =YEAR(A16) -> 2025 | E16: 14 | F16: 248623393 | G16: XZ | H16: PZU | I16: LE0001 | J16: LENTIL TAT 20KG | L16: 23 | M16: =VLOOKUP(Table1[[#This Row],[BL NO.]],'BL NCs'!$E$3:$K$78,7,0) -> 23 | O16: Short | P16: 0 | Q16: 0 | R16: =Table1[[#This Row],[Torn QTY]]-Table1[[#This Row],[loss]] -> 0 | S16: 20KG BAGS | T16: Import Container Damage/Short | U16: Marine Insurance | V16: Import | W16: 23 bags found shortage at container BL:248623393. for short bags is less than deductable 0.5%. | X16: CIS report/LOP | Y16: 22.71 | Z16: =Y16*M16 -> 522.33 | AA16: 58000 | AB16: =AA16*M16 -> 1334000 | AC16: 50018.235 | AD16: =AC16*M16 -> 1150419.4 | AE16: =AR16 -> 0 | AF16: 2554.48 | AG16: Loss | AH16: Adjusted | AI16: Ajay/Limitz | AJ16: Post-War | AK16: Rawan | AM16: Accept | AN16: Close | AO16: Less than deductible | AQ16: =Z16 -> 522.33 | AR16: 0 | AS16: =AQ16-AR16 -> 522.33 | AT16: =(AR16/AQ16-1)*-1 -> 1 | AU16: Less than deductible (0.5%)
A17: 45770 | B17: S7 | C17: =TEXT(A17,"MMM") -> Apr | D17: =YEAR(A17) -> 2025 | E17: 15 | F17: 248623928 | G17: XZ | H17: PZU | I17: LE0001 | J17: LENTIL TAT 20KG | L17: 33 | M17: =VLOOKUP(Table1[[#This Row],[BL NO.]],'BL NCs'!$E$3:$K$78,7,0) -> 33 | O17: 53-Short | P17: 0 | Q17: 0 | R17: =Table1[[#This Row],[Torn QTY]]-Table1[[#This Row],[loss]] -> 0 | S17: 20KG BAGS | T17: Import Container Damage/Short | U17: Marine Insurance | V17: Import | W17: 33 bags found shortage at container BL:248623928 | X17: CIS report/LOP | Y17: 22.71 | Z17: =Y17*M17 -> 749.43 | AA17: 58000 | AB17: =AA17*M17 -> 1914000 | AC17: 50018.235 | AD17: =AC17*M17 -> 1650601.7 | AE17: =AR17 -> 0 | AF17: 2554.48 | AG17: Loss | AH17: Adjusted | AI17: Ajay/Limitz | AJ17: Post-War | AK17: Rawan | AM17: Accept | AN17: Close | AO17: Less than deductible | AQ17: =Z17 -> 749.43 | AR17: 0 | AS17: =AQ17-AR17 -> 749.43 | AT17: =(AR17/AQ17-1)*-1 -> 1 | AU17: Less than deductible (0.5%)
A18: 45860 | B18: S7 | C18: =TEXT(A18,"MMM") -> Jul | D18: =YEAR(A18) -> 2025 | E18: 16 | F18: CAEMER25262000 | G18: XI | H18: PZU-Bond area | I18: LE0001 | J18: LENTIL TAT 20KG | L18: 52 | M18: =VLOOKUP(Table1[[#This Row],[BL NO.]],'BL NCs'!$E$3:$K$78,7,0) -> 6 | O18: Not found | P18: 0 | Q18: 0 | R18: =Table1[[#This Row],[Torn QTY]]-Table1[[#This Row],[loss]] -> 0 | S18: 20KG BAGS | T18: Import Container Damage/Short | U18: Marine Insurance | V18: Import | W18: 46 torn 6 wet bag during discharge CAEMER25262000.Torn bags are not covered under insurance. wet bag less than deductable 0.5% | X18: CIS report | Y18: 18.54 | Z18: =Y18*M18 -> 111.24 | AA18: =Y18*AF18 -> 51967.62 | AB18: =AA18*M18 -> 311805.72 | AC18: 41075.795 | AD18: =AC18*M18 -> 246454.77 | AE18: =AR18 -> 0 | AF18: 2803 | AG18: Loss | AH18: N/A | AI18: Ajay/Jeenu | AJ18: Post-War | AK18: Rawan | AM18: Reject | AN18: Close | AO18: Not include under insurance covarge/Less than deductable | AQ18: =Z18 -> 111.24 | AR18: 0 | AS18: =AQ18-AR18 -> 111.24 | AT18: =(AR18/AQ18-1)*-1 -> 1 | AU18: Not include under insurance covarge/Less than deductable (0.5%)
A19: 45860 | B19: S7 | C19: =TEXT(A19,"MMM") -> Jul | D19: =YEAR(A19) -> 2025 | E19: 17 | F19: CAEMER25262001 | G19: XI | H19: PZU-Bond area | I19: LE0001 | J19: LENTIL TAT 20KG | L19: 54 | M19: =VLOOKUP(Table1[[#This Row],[BL NO.]],'BL NCs'!$E$3:$K$78,7,0) -> 3 | O19: Not found | P19: 0 | Q19: 0 | R19: =Table1[[#This Row],[Torn QTY]]-Table1[[#This Row],[loss]] -> 0 | S19: 20KG BAGS | T19: Import Container Damage/Short | U19: Marine Insurance | V19: Import | W19: 51 torn bag 3 wet bag during discharge CAEMER25262001. Torn bag not cover under insurance, for wet bags less than deductable .05%. | X19: CIS report | Y19: 18.54 | Z19: =Y19*M19 -> 55.62 | AA19: 51967.62 | AB19: =AA19*M19 -> 155902.86 | AC19: 41075.795 | AD19: =AC19*M19 -> 123227.39 | AE19: =AR19 -> 0 | AF19: 2803 | AG19: Loss | AH19: N/A | AI19: Ajay/Jeenu | AJ19: Post-War | AK19: Rawan | AM19: Reject | AN19: Close | AO19: Not include under insurance covarge | AQ19: =Z19 -> 55.62 | AR19: 0 | AS19: =AQ19-AR19 -> 55.62 | AT19: =(AR19/AQ19-1)*-1 -> 1 | AU19: Case Reject/No compensation
A20: 45860 | B20: S7 | C20: =TEXT(A20,"MMM") -> Jul | D20: =YEAR(A20) -> 2025 | E20: 18 | F20: CAEMER25262002 | G20: XI | H20: PZU-Bond area | I20: LE0001 | J20: LENTIL TAT 20KG | L20: 67 | M20: =VLOOKUP(Table1[[#This Row],[BL NO.]],'BL NCs'!$E$3:$K$78,7,0) -> 5 | O20: Not found | P20: 0 | Q20: 0 | R20: =Table1[[#This Row],[Torn QTY]]-Table1[[#This Row],[loss]] -> 0 | S20: 20KG BAGS | T20: Import Container Damage/Short | U20: Marine Insurance | V20: Import | W20: 52 torn bag 5 wet bag during discharge CAEMER25262002. Torn bag not cover under insurance, for wet bags less than deductable .05%. | X20: CIS report/Wet LOP | Y20: 18.54 | Z20: =Y20*M20 -> 92.7 | AA20: 51967.62 | AB20: =AA20*M20 -> 259838.1 | AC20: 41075.795 | AD20: =AC20*M20 -> 205378.98 | AE20: =AR20 -> 0 | AF20: 2803 | AG20: Loss | AH20: N/A | AI20: Ajay/Jeenu | AJ20: Post-War | AK20: Rawan | AM20: Reject | AN20: Close | AO20: Not include under insurance covarge | AQ20: =Z20 -> 92.7 | AR20: 0 | AS20: =AQ20-AR20 -> 92.7 | AT20: =(AR20/AQ20-1)*-1 -> 1 | AU20: Case Reject/No compensation
A21: 45875 | B21: S7 | C21: =TEXT(A21,"MMM") -> Aug | D21: =YEAR(A21) -> 2025 | E21: 19 | F21: CAEMER25310000 | G21: XI | H21: PZU-Bond area | I21: LE0001 | J21: LENTIL TAT 20KG | L21: 50 | M21: =VLOOKUP(Table1[[#This Row],[BL NO.]],'BL NCs'!$E$3:$K$78,7,0) -> 23 | O21: 47 | P21: 50 | Q21: 23 | R21: =Table1[[#This Row],[Torn QTY]]-Table1[[#This Row],[loss]] -> 27 | S21: 20KG BAGS | T21: Import Container Damage/Short | U21: Marine Insurance | V21: Import | W21: 50 torn bag during discharge CAEMER25310000, case reject due there is excess at BL by 207 bags. | X21: CIS report | Y21: 18.54 | Z21: =Y21*M21 -> 426.42 | AA21: 51967.62 | AB21: =AA21*M21 -> 1195255.3 | AC21: 53401.106 | AD21: =AC21*M21 -> 1228225.4 | AE21: =AR21 -> 0 | AF21: 2803 | AG21: Loss | AH21: N/A | AI21: Ajay/Jeenue | AJ21: Post-War | AK21: Rawan | AM21: Reject | AN21: Close | AO21: Not include under insurance covarge | AQ21: =Z21 -> 426.42 | AR21: 0 | AS21: =AQ21-AR21 -> 426.42 | AT21: =(AR21/AQ21-1)*-1 -> 1 | AU21: Case Reject/No compensation
A22: 45875 | B22: S7 | C22: =TEXT(A22,"MMM") -> Aug | D22: =YEAR(A22) -> 2025 | E22: 20 | F22: CAEMER25310001 | G22: XI | H22: PZU-Bond area | I22: LE0001 | J22: LENTIL TAT 20KG | L22: 46 | M22: =VLOOKUP(Table1[[#This Row],[BL NO.]],'BL NCs'!$E$3:$K$78,7,0) -> 23 | O22: 47 | P22: 46 | Q22: 23 | R22: =Table1[[#This Row],[Torn QTY]]-Table1[[#This Row],[loss]] -> 23 | S22: 20KG BAGS | T22: Import Container Damage/Short | U22: Marine Insuranse | V22: Import | W22: 46 torn bag during descharge CAEMER25310001,Case rject due there is ecxess at BL by 154 bags. | X22: CIS report | Y22: 18.54 | Z22: =Y22*M22 -> 426.42 | AA22: 51967.62 | AB22: =AA22*M22 -> 1195255.3 | AC22: 53401.106 | AD22: =AC22*M22 -> 1228225.4 | AE22: =AR22 -> 0 | AF22: 2803 | AG22: Loss | AH22: N/A | AI22: Ajay/Jeenue | AJ22: Post-War | AK22: Rawan | AM22: Reject | AN22: Close | AO22: Not include under insurance covarge | AQ22: =Z22 -> 426.42 | AR22: 0 | AS22: =AQ22-AR22 -> 426.42 | AT22: =(AR22/AQ22-1)*-1 -> 1 | AU22: Not include under insurance covarge
A23: 45916 | B23: S7 | C23: =TEXT(A23,"MMM") -> Sep | D23: =YEAR(A23) -> 2025 | E23: 21 | F23: CAEMER25406100 | G23: XI | H23: PZU-Bond area | I23: LE0001 | J23: LENTIL TAT 20KG | L23: 87 | M23: =VLOOKUP(Table1[[#This Row],[BL NO.]],'BL NCs'!$E$3:$K$78,7,0) -> 27 | O23: 69 | P23: 80 | Q23: 20 | R23: =Table1[[#This Row],[Torn QTY]]-Table1[[#This Row],[loss]] -> 60 | S23: 20KG BAGS | T23: Import Container Damage/Short | U23: Marine Insuranse | V23: Import | W23: 80 torn bag during descharge and 7 wet bags, BL:CAEMER25406100, torn bags are not covered under the insurance. However, extra empty bags were shipped along with the cargo, which can be used to rebag, for wet bag less than deductable .05% | X23: CIS report | Y23: 18.38 | Z23: =Y23*M23 -> 496.26 | AA23: =Y23*AF23 -> 61936.924 | AB23: =AA23*M23 -> 1672296.9 | AC23: 45680.802 | AD23: =AC23*M23 -> 1233381.6 | AE23: 0 | AF23: 3369.8 | AG23: Loss | AH23: N/A | AI23: Ajay/Jeenue | AJ23: Post-War | AK23: Rawan | AM23: Reject | AN23: Close | AO23: Not include under insurance covarge/Less than deductable | AQ23: =Z23 -> 496.26 | AR23: 0 | AS23: =AQ23-AR23 -> 496.26 | AT23: =(AR23/AQ23-1)*-1 -> 1 | AU23: Not include under insurance covarge/Less than deductable (0.5%)
A24: 45916 | C24: =TEXT(A24,"MMM") -> Sep | D24: =YEAR(A24) -> 2025 | E24: 22 | F24: CAEMER25406101 | G24: XI | H24: PZU-Bond area | I24: LE0001 | J24: LENTIL TAT 20KG | L24: 60 | M24: =VLOOKUP(Table1[[#This Row],[BL NO.]],'BL NCs'!$E$3:$K$78,7,0) -> 18 | O24: 70 | P24: 60 | Q24: 18 | R24: =Table1[[#This Row],[Torn QTY]]-Table1[[#This Row],[loss]] -> 42 | S24: 20KG BAGS | T24: Import Container Damage/Short | U24: Marine Insuranse | V24: Import | W24: 60 torn bag during descharge, BL:CAEMER25406101, torn bags are not covered under the insurance. However, extra empty bags were shipped along with the cargo, which can be used to rebag | X24: CIS report | Y24: 18.38 | Z24: =Y24*M24 -> 330.84 | AA24: =Y24*AF24 -> 61936.924 | AB24: =AA24*M24 -> 1114864.6 | AC24: 45680.802 | AD24: =AC24*M24 -> 822254.43 | AE24: 0 | AF24: 3369.8 | AG24: Loss | AH24: N/A | AI24: Ajay/Jeenue | AJ24: Post-War | AK24: Rawan | AM24: Reject | AN24: Close | AO24: Not include under insurance covarge | AQ24: =Z24 -> 330.84 | AR24: 0 | AS24: =AQ24-AR24 -> 330.84 | AT24: =(AR24/AQ24-1)*-1 -> 1 | AU24: Not include under insurance covarge
A25: 45930 | C25: =TEXT(A25,"MMM") -> Sep | D25: =YEAR(A25) -> 2025 | E25: 23 | F25: 257625382 | G25: XI | H25: PZU-Bond area | I25: LE0001 | J25: LENTIL TAT 20KG | L25: 40 | M25: =VLOOKUP(Table1[[#This Row],[BL NO.]],'BL NCs'!$E$3:$K$78,7,0) -> 11 | O25: 75 | P25: 40 | Q25: 11 | R25: =Table1[[#This Row],[Torn QTY]]-Table1[[#This Row],[loss]] -> 29 | S25: 20KG BAGS | T25: Import Container Damage/Short | U25: Marine Insuranse | V25: Import | W25: 40 torn bag during descharge BL:257625382.Torn bags are not covered under insurance. | X25: CIS report | Y25: 18.38 | Z25: =Y25*M25 -> 202.18 | AA25: =Y25*AF25 -> 61936.924 | AB25: =AA25*M25 -> 681306.16 | AC25: 45680.802 | AD25: =AC25*M25 -> 502488.82 | AE25: 0 | AF25: 3369.8 | AG25: Loss | AH25: N/A | AI25: Ajay/Jeenue | AJ25: Post-War | AK25: Rawan | AM25: Reject | AN25: Close | AO25: Not include under insurance covarge | AQ25: =Z25 -> 202.18 | AR25: 0 | AS25: =AQ25-AR25 -> 202.18 | AT25: =(AR25/AQ25-1)*-1 -> 1 | AU25: Not include under insurance covarge
A26: 45946 | B26: S7 | C26: =TEXT(A26,"MMM") -> Oct | D26: =YEAR(A26) -> 2025 | E26: 24 | F26: CAEMER25481600 | G26: XI | H26: PZU-Bond area | I26: LE0001 | J26: LENTIL TAT 20KG | L26: 42 | M26: =VLOOKUP(Table1[[#This Row],[BL NO.]],'BL NCs'!$E$3:$K$78,7,0) -> 14 | O26: 83 | P26: 42 | Q26: 14 | R26: =Table1[[#This Row],[Torn QTY]]-Table1[[#This Row],[loss]] -> 28 | S26: 20KG BAGS | T26: Import Container Damage/Short | U26: Marine Insuranse | V26: Import | W26: 42 torn bag during descharge BL:CAEMER25481600. Torn bags are not covered under insurance. | X26: CIS report | Y26: 18.38 | Z26: =Y26*M26 -> 257.32 | AA26: =Y26*AF26 -> 61936.924 | AB26: =AA26*M26 -> 867116.94 | AC26: 45681 | AD26: =AC26*M26 -> 639534 | AE26: 0 | AF26: 3369.8 | AG26: Loss | AH26: N/A | AI26: Jeenue | AJ26: Post-War | AK26: Rawan | AM26: Reject | AN26: Close | AO26: Not include under insurance covarge | AQ26: =Z26 -> 257.32 | AR26: 0 | AS26: =AQ26-AR26 -> 257.32 | AT26: =(AR26/AQ26-1)*-1 -> 1 | AU26: Not include under insurance covarge
A27: 45946 | C27: =TEXT(A27,"MMM") -> Oct | D27: =YEAR(A27) -> 2025 | E27: 25 | F27: CAEMER25481700 | G27: XI | H27: PZU-Bond area | I27: LE0001 | J27: LENTIL TAT 20KG | L27: 41 | M27: =VLOOKUP(Table1[[#This Row],[BL NO.]],'BL NCs'!$E$3:$K$78,7,0) -> 17 | O27: 84 | P27: 41 | Q27: 17 | R27: =Table1[[#This Row],[Torn QTY]]-Table1[[#This Row],[loss]] -> 24 | S27: 20KG BAGS | T27: Import Container Damage/Short | U27: Marine Insuranse | V27: Import | W27: 41 torn bag during descharge BL: CAEMER25481700. Torn bags are not covered under insurance | X27: CIS report | Y27: 18.38 | Z27: =Y27*M27 -> 312.46 | AA27: =Y27*AF27 -> 61936.924 | AB27: =AA27*M27 -> 1052927.7 | AC27: 45681 | AD27: =AC27*M27 -> 776577 | AE27: 0 | AF27: 3369.8 | AG27: Loss | AH27: N/A | AI27: Jeenue | AJ27: Post-War | AK27: Rawan | AM27: Reject | AN27: Close | AO27: Not include under insurance covarge | AQ27: =Z27 -> 312.46 | AR27: 0 | AS27: =AQ27-AR27 -> 312.46 | AT27: =(AR27/AQ27-1)*-1 -> 1 | AU27: Not include under insurance covarge
A28: 45929 | B28: S7 | C28: =TEXT(A28,"MMM") -> Sep | D28: =YEAR(A28) -> 2025 | E28: 26 | F28: SHNSAPZU25070094 | G28: XI | H28: PZU-Bond area | I28: RC0004 | J28: RICE LONG ELNGM 20K | L28: 127 | M28: =VLOOKUP(Table1[[#This Row],[BL NO.]],'BL NCs'!$E$3:$K$78,7,0) -> 116 | O28: 122&125-Comment | P28: 40 | Q28: =16+3+4 -> 23 | R28: =Table1[[#This Row],[Torn QTY]]-Table1[[#This Row],[loss]] -> 17 | S28: 20KG BAGS | T28: Import Container Damage/Short | U28: Marine Insuranse | V28: Import | W28: 40 torn bag/4 wet bag/83 shortagebag BL:SHNSAPZU25070094 all reqirment documents share, first notification on 29-Sep-25 the final CIS report with final quantity on 17-Oct-25.Torn bags are not covered under insurance for short and wet bag less than deductable .05% | X28: CIS report/LOP/e claim form/Claim report form | Y28: 11.41 | Z28: =Y28*M28 -> 1323.56 | AA28: =Y28*AF28 -> 38449.418 | AB28: =AA28*M28 -> 4460132.5 | AC28: 31023 | AD28: =AC28*M28 -> 3598668 | AE28: 0 | AF28: 3369.8 | AG28: Loss | AH28: Adjusted | AI28: Jeenue | AJ28: Post-War | AK28: Rawan | AM28: Accept | AN28: Close | AO28: Not include under insurance covarge/Less than deductable | AQ28: =Z28 -> 1323.56 | AR28: 0 | AS28: =AQ28-AR28 -> 1323.56 | AT28: =(AR28/AQ28-1)*-1 -> 1 | AU28: Not include under insurance covarge/Less than deductable (0.5%)
A29: 45953 | B29: S7 | C29: =TEXT(A29,"MMM") -> Oct | D29: =YEAR(A29) -> 2025 | E29: 27 | F29: 258447410 | G29: XI | H29: PZU-Bond area | I29: LE0001 | J29: LENTIL TAT 20KG | L29: 46 | M29: =VLOOKUP(Table1[[#This Row],[BL NO.]],'BL NCs'!$E$3:$K$78,7,0) -> 34 | O29: 86-Comment | P29: 18 | Q29: 6 | R29: =Table1[[#This Row],[Torn QTY]]-Table1[[#This Row],[loss]] -> 12 | S29: 20KG BAGS | T29: Import Container Damage/Short | U29: Marine Insuranse | V29: Import | W29: 18 torn bag / 28 short bag BL:258447410. As Dubai team email Torn bags are not covered under insurance. | X29: CIS report/LOP | Y29: 17.416 | Z29: =Y29*M29 -> 592.144 | AA29: =Y29*AF29 -> 58688.437 | AB29: =AA29*M29 -> 1995406.9 | AC29: 45681 | AD29: =AC29*M29 -> 1553154 | AE29: 0 | AF29: 3369.8 | AG29: Pending | AH29: Adjusted | AI29: Jeenue | AJ29: Post-War | AK29: Rawan | AM29: Pending | AN29: Pending | AO29: Case submitted/ Waiting Insurance feedback | AQ29: =Z29 -> 592.144 | AR29: 0 | AS29: =AQ29-AR29 -> 592.144 | AT29: =(AR29/AQ29-1)*-1 -> 1 | AU29: Waiting Feedback
A30: 45959 | B30: S7 | C30: =TEXT(A30,"MMM") -> Oct | D30: =YEAR(A30) -> 2025 | E30: 28 | F30: ASN/PZU/0825/11093 | G30: XI | H30: PZU-Bond area | I30: RC0004 | J30: RICE LONG ELNGM 20K | L30: 258 | M30: =VLOOKUP(Table1[[#This Row],[BL NO.]],'BL NCs'!$E$3:$K$78,7,0) -> 255 | O30: 93&94-Comment | P30: 48 | Q30: 9 | R30: =Table1[[#This Row],[Torn QTY]]-Table1[[#This Row],[loss]] -> 39 | S30: 20KG BAGS | T30: Import Container Damage/Short | U30: Marine Insuranse | V30: Import | W30: 48 torn bag/ 85 wet bags/ 125 short bags BL:ASN/PZU/0825/11093, As email from Jeenu torn bag not cover under insurance. There is Final report update at 7 December 2025- 48 torn bag/ 129 wet bags/ 81 short bags but insurance not accept the update, they accept the first servey report. | X30: CIS report/LOP | Y30: 8.75 | Z30: =Y30*M30 -> 2231.25 | AA30: =Y30*AF30 -> 31041.413 | AB30: =AA30*M30 -> 7915560.2 | AC30: 23264.087 | AD30: =AC30*M30 -> 5932342.3 | AE30: 0 | AF30: 3547.59 | AG30: Pending | AH30: Adjusted | AI30: Jeenue | AJ30: Post-War | AK30: Rawan | AM30: Pending | AN30: Pending | AO30: Case submitted/ Waiting Insurance feedback | AQ30: =Z30 -> 2231.25 | AR30: 0 | AS30: =AQ30-AR30 -> 2231.25 | AT30: =(AR30/AQ30-1)*-1 -> 1 | AU30: Waiting Feedback
A31: 45966 | B31: S7 | C31: =TEXT(A31,"MMM") -> Nov | D31: =YEAR(A31) -> 2025 | E31: 29 | F31: 2501094EXY | G31: XI | H31: PZU-Bond area | I31: LE0001 | J31: LENTIL TAT 20KG | L31: 33 | M31: =VLOOKUP(Table1[[#This Row],[BL NO.]],'BL NCs'!$E$3:$K$78,7,0) -> 9 | O31: 89 | P31: 33 | Q31: 8 | R31: =Table1[[#This Row],[Torn QTY]]-Table1[[#This Row],[loss]] -> 25 | S31: 20KG BAGS | T31: Import Container Damage/Short | U31: Marine Insuranse | V31: Import | W31: 33 torn bag during descharge BL: 2501094EXY, As email from Jeenu torn bag not cover under insurance. | X31: CIS report | Y31: 16.52 | Z31: =Y31*M31 -> 148.68 | AA31: =Y31*AF31 -> 58606.187 | AB31: =AA31*M31 -> 527455.68 | AC31: 42710.473 | AD31: =AC31*M31 -> 384394.26 | AE31: 0 | AF31: 3547.59 | AG31: Loss | AH31: N/A | AI31: Jeenue | AJ31: Post-War | AK31: Rawan | AM31: Reject | AN31: Close | AO31: Not include under insurance covarge | AQ31: =Z31 -> 148.68 | AR31: 0 | AS31: =AQ31-AR31 -> 148.68 | AT31: =(AR31/AQ31-1)*-1 -> 1 | AU31: Not include under insurance covarge
A32: 45966 | C32: =TEXT(A32,"MMM") -> Nov | D32: =YEAR(A32) -> 2025 | E32: 30 | F32: 2501095EXY | G32: XI | H32: PZU-Bond area | I32: LE0001 | J32: LENTIL TAT 20KG | L32: 71 | M32: =VLOOKUP(Table1[[#This Row],[BL NO.]],'BL NCs'!$E$3:$K$78,7,0) -> 16 | O32: 90 | P32: 71 | Q32: 14 | R32: =Table1[[#This Row],[Torn QTY]]-Table1[[#This Row],[loss]] -> 57 | S32: 20KG BAGS | T32: Import Container Damage/Short | U32: Marine Insuranse | V32: Import | W32: 71 torn bags during descharge BL: 2501095EXY, As email from Jeenu torn bag not cover under insurance. | X32: CIS report | Y32: 16.52 | Z32: =Y32*M32 -> 264.32 | AA32: =Y32*AF32 -> 58606.187 | AB32: =AA32*M32 -> 937698.99 | AC32: 42710.473 | AD32: =AC32*M32 -> 683367.57 | AE32: 0 | AF32: 3547.59 | AG32: Loss | AH32: N/A | AI32: Jeenue | AJ32: Post-War | AK32: Rawan | AM32: Reject | AN32: Close | AO32: Not include under insurance covarge | AQ32: =Z32 -> 264.32 | AR32: 0 | AS32: =AQ32-AR32 -> 264.32 | AT32: =(AR32/AQ32-1)*-1 -> 1 | AU32: Not include under insurance covarge
A33: 45972 | B33: S7 | C33: =TEXT(A33,"MMM") -> Nov | D33: =YEAR(A33) -> 2025 | E33: 31 | F33: 259338012 | G33: XI | H33: PZU-Bond area | I33: LE0001 | J33: LENTIL TAT 20KG | L33: 44 | M33: =VLOOKUP(Table1[[#This Row],[BL NO.]],'BL NCs'!$E$3:$K$78,7,0) -> 5 | O33: 95 | P33: 44 | Q33: 5 | R33: =Table1[[#This Row],[Torn QTY]]-Table1[[#This Row],[loss]] -> 39 | S33: 20KG BAGS | T33: Import Container Damage/Short | U33: Marine Insuranse | V33: Import | W33: 44 torn bag during descharge BL: 259338012 ,As email from Jeenu torn bag not cover under insurance.. | X33: CIS report | Y33: 17.43 | Z33: =Y33*M33 -> 87.15 | AA33: =Y33*AF33 -> 61834.494 | AB33: =AA33*M33 -> 309172.47 | AC33: 42710.473 | AD33: =AC33*M33 -> 213552.37 | AE33: 0 | AF33: 3547.59 | AG33: Loss | AH33: N/A | AI33: Jeenue | AJ33: Post-War | AK33: Rawan | AM33: Reject | AN33: Close | AO33: Not include under insurance covarge | AQ33: =Z33 -> 87.15 | AR33: 0 | AS33: =AQ33-AR33 -> 87.15 | AT33: =(AR33/AQ33-1)*-1 -> 1 | AU33: Not include under insurance covarge
A34: 45972 | C34: =TEXT(A34,"MMM") -> Nov | D34: =YEAR(A34) -> 2025 | E34: 32 | F34: 259649778 | G34: XI | H34: PZU-Bond area | I34: LE0001 | J34: LENTIL TAT 20KG | L34: 23 | M34: =VLOOKUP(Table1[[#This Row],[BL NO.]],'BL NCs'!$E$3:$K$78,7,0) -> 7 | O34: 96 | P34: 23 | Q34: 7 | R34: =Table1[[#This Row],[Torn QTY]]-Table1[[#This Row],[loss]] -> 16 | S34: 20KG BAGS | T34: Import Container Damage/Short | U34: Marine Insuranse | V34: Import | W34: 23 torn bags during descharge BL: 259649778 ,As email from Jeenu torn bag not cover under insurance. | X34: CIS report | Y34: 17.43 | Z34: =Y34*M34 -> 122.01 | AA34: =Y34*AF34 -> 61834.494 | AB34: =AA34*M34 -> 432841.46 | AC34: 42710.473 | AD34: =AC34*M34 -> 298973.31 | AE34: 0 | AF34: 3547.59 | AG34: Loss | AH34: N/A | AI34: Jeenue | AJ34: Post-War | AK34: Rawan | AM34: Reject | AN34: Close | AO34: Not include under insurance covarge | AQ34: =Z34 -> 122.01 | AR34: 0 | AS34: =AQ34-AR34 -> 122.01 | AT34: =(AR34/AQ34-1)*-1 -> 1 | AU34: Not include under insurance covarge
A35: 45978 | B35: S7 | C35: =TEXT(A35,"MMM") -> Nov | D35: =YEAR(A35) -> 2025 | E35: 33 | F35: 2501096EXY | G35: XI | H35: PZU-Bond area | I35: LE0001 | J35: LENTIL TAT 20KG | L35: 84 | M35: =VLOOKUP(Table1[[#This Row],[BL NO.]],'BL NCs'!$E$3:$K$78,7,0) -> 19 | O35: 100 | P35: 84 | Q35: 19 | R35: =Table1[[#This Row],[Torn QTY]]-Table1[[#This Row],[loss]] -> 65 | S35: 20KG BAGS | T35: Import Container Damage/Short | U35: Marine Insuranse | V35: Import | W35: 84 torn bag BL:2501096EXY, As email from Jeenu torn bag not cover under insurance. | X35: CIS report | Y35: 16.52 | Z35: =Y35*M35 -> 313.88 | AA35: =Y35*AF35 -> 58606.187 | AB35: =AA35*M35 -> 1113517.5 | AC35: 42710.473 | AD35: =AC35*M35 -> 811498.99 | AE35: 0 | AF35: 3547.59 | AG35: Loss | AH35: N/A | AI35: Jeenue | AJ35: Post-War | AK35: Rawan | AM35: Reject | AN35: Close | AO35: Not include under insurance covarge | AQ35: =Z35 -> 313.88 | AR35: 0 | AS35: =AQ35-AR35 -> 313.88 | AT35: =(AR35/AQ35-1)*-1 -> 1 | AU35: Not include under insurance covarge
A36: 45979 | B36: S7 | C36: =TEXT(A36,"MMM") -> Nov | D36: =YEAR(A36) -> 2025 | E36: 34 | F36: CAEMER25549700 | G36: XI | H36: PZU-Bond area | I36: LE0001 | J36: LENTIL TAT 20KG | L36: 57 | M36: =VLOOKUP(Table1[[#This Row],[BL NO.]],'BL NCs'!$E$3:$K$78,7,0) -> 8 | O36: 101 | P36: 57 | Q36: 8 | R36: =Table1[[#This Row],[Torn QTY]]-Table1[[#This Row],[loss]] -> 49 | S36: 20KG BAGS | T36: Import Container Damage/Short | U36: Marine Insuranse | V36: Import | W36: 57 torn bag BL:CAEMER25549700.As feedback from Jeenu torn bag not cover under insurance. | X36: CIS report | Y36: 16.52 | Z36: =Y36*M36 -> 132.16 | AA36: =Y36*AF36 -> 58606.187 | AB36: =AA36*M36 -> 468849.49 | AC36: 42711.473 | AD36: =AC36*M36 -> 341691.79 | AE36: 0 | AF36: 3547.59 | AG36: Loss | AH36: N/A | AI36: Jeenue | AJ36: Post-War | AK36: Rawan | AM36: Reject | AN36: Close | AO36: Not include under insurance covarge | AQ36: =Z36 -> 132.16 | AR36: 0 | AS36: =AQ36-AR36 -> 132.16 | AT36: =(AR36/AQ36-1)*-1 -> 1 | AU36: Not include under insurance covarge
A37: 45993 | B37: S7 | C37: =TEXT(A37,"MMM") -> Dec | D37: =YEAR(A37) -> 2025 | E37: 35 | F37: 257625599 | G37: XI | H37: PZU-Bond area | I37: LE0001 | J37: LENTIL TAT 20KG | L37: 35 | M37: =VLOOKUP(Table1[[#This Row],[BL NO.]],'BL NCs'!$E$3:$K$78,7,0) -> 9 | O37: 76-Comment | P37: 35 | Q37: 9 | R37: =Table1[[#This Row],[Torn QTY]]-Table1[[#This Row],[loss]] -> 26 | S37: 20KG BAGS | T37: Import Container Damage/Short | U37: Marine Insuranse | V37: Import | W37: 35 torn bag BL:257625599.Torn bags are not covered under insurance | X37: CIS report | Y37: 17.744 | Z37: =Y37*M37 -> 159.696 | AA37: =Y37*AF37 -> 63437.994 | AB37: =AA37*M37 -> 570941.95 | AC37: 23264.087 | AD37: =AC37*M37 -> 209376.79 | AE37: 0 | AF37: 3575.18 | AG37: Loss | AH37: N/A | AI37: Jeenue | AJ37: Post-War | AK37: Rawan | AM37: Reject | AN37: Close | AO37: Not include under insurance covarge | AQ37: =Z37 -> 159.696 | AR37: 0 | AS37: =AQ37-AR37 -> 159.696 | AT37: =(AR37/AQ37-1)*-1 -> 1 | AU37: Not include under insurance covarge
A38: 45993 | C38: =TEXT(A38,"MMM") -> Dec | D38: =YEAR(A38) -> 2025 | E38: 36 | F38: 257625490 | G38: XI | H38: PZU-Bond area | I38: LE0001 | J38: LENTIL TAT 20KG | L38: 37 | M38: =VLOOKUP(Table1[[#This Row],[BL NO.]],'BL NCs'!$E$3:$K$78,7,0) -> 17 | O38: 82&99-Comment | P38: 37 | Q38: 13 | R38: =Table1[[#This Row],[Torn QTY]]-Table1[[#This Row],[loss]] -> 24 | S38: 20KG BAGS | T38: Import Container Damage/Short | U38: Marine Insuranse | V38: Import | W38: 37 torn bag BL:257625490.Torn bags are not covered under insurance | X38: CIS report | Y38: 17.744 | Z38: =Y38*M38 -> 301.648 | AA38: =Y38*AF38 -> 63437.994 | AB38: =AA38*M38 -> 1078445.9 | AC38: 23264.087 | AD38: =AC38*M38 -> 395489.48 | AE38: 0 | AF38: 3575.18 | AG38: Loss | AH38: N/A | AI38: Jeenue | AJ38: Post-War | AK38: Rawan | AM38: Reject | AN38: Close | AO38: Not include under insurance covarge | AQ38: =Z38 -> 301.648 | AR38: 0 | AS38: =AQ38-AR38 -> 301.648 | AT38: =(AR38/AQ38-1)*-1 -> 1 | AU38: Not include under insurance covarge
A39: 45993 | C39: =TEXT(A39,"MMM") -> Dec | D39: =YEAR(A39) -> 2025 | E39: 37 | F39: 257906213 | G39: XI | H39: PZU-Bond area | I39: LE0001 | J39: LENTIL TAT 20KG | L39: =24+28 -> 52 | M39: =VLOOKUP(Table1[[#This Row],[BL NO.]],'BL NCs'!$E$3:$K$78,7,0) -> 6 | O39: 80&98-Comment | P39: 28 | Q39: =5+1 -> 6 | R39: =Table1[[#This Row],[Torn QTY]]-Table1[[#This Row],[loss]] -> 22 | S39: 20KG BAGS | T39: Import Container Damage/Short | U39: Marine Insuranse | V39: Import | W39: 28 torn bag/ 24 Hight Polish bag BL:257906213.Torn bags are not covered under insurance. The high polished 24 bags, less than tolirance 0.5%. | X39: CIS report | Y39: 17.744 | Z39: =Y39*M39 -> 106.464 | AA39: =Y39*AF39 -> 63437.994 | AB39: =AA39*M39 -> 380627.96 | AC39: 23264.087 | AD39: =AC39*M39 -> 139584.52 | AE39: 0 | AF39: 3575.18 | AG39: Loss | AH39: N/A | AI39: Jeenue | AJ39: Post-War | AK39: Rawan | AM39: Reject | AN39: Close | AO39: Not include under insurance covarge/Less than deductable | AQ39: =Z39 -> 106.464 | AR39: 0 | AS39: =AQ39-AR39 -> 106.464 | AT39: =(AR39/AQ39-1)*-1 -> 1 | AU39: Not include under insurance covarge/Less than deductable (0.5%)
A40: 46006 | B40: S7 | C40: =TEXT(A40,"MMM") -> Dec | D40: =YEAR(A40) -> 2025 | E40: 38 | F40: CAEMER25645400 | G40: XI | H40: PZU-Bond area | I40: LE0001 | J40: LENTIL TAT 20KG | L40: 55 | M40: =VLOOKUP(Table1[[#This Row],[BL NO.]],'BL NCs'!$E$3:$K$78,7,0) -> 8 | O40: 102 | P40: 55 | Q40: 8 | R40: =Table1[[#This Row],[Torn QTY]]-Table1[[#This Row],[loss]] -> 47 | S40: 20KG BAGS | T40: Import Container Damage/Short | U40: Marine Insuranse | V40: Import | W40: 55 torn bag BL:CAEMER25645400.Torn bags are not covered under insurance. After repacking there is loss 8 bags | X40: CIS report | Y40: 16.2087 | Z40: =Y40*M40 -> 129.6696 | AA40: =Y40*AF40 -> 57949.02 | AB40: =AA40*M40 -> 463592.16 | AC40: 42710.737 | AD40: =AC40*M40 -> 341685.89 | AE40: 0 | AF40: 3575.18 | AG40: Loss | AH40: N/A | AI40: Jeenue | AJ40: Post-War | AK40: Rawan | AM40: Reject | AN40: Close | AO40: Not include under insurance covarge | AQ40: =Z40 -> 129.6696 | AR40: 0 | AS40: =AQ40-AR40 -> 129.6696 | AT40: =(AR40/AQ40-1)*-1 -> 1 | AU40: Not include under insurance covarge
...

Sheet BL NCs
N1: Survey report QTY | S1: Torn repacking result | V1: High-polish repacking result | Y1: Defected Qty after Repacking Results | AB1: Local sale value | AN1: Claim amount calculation
A2: Date | B2: Month | C2: Year | D2: Case Number | E2: BL NO. | F2: WH | G2: Location | H2: Product | I2: Product Description | J2: Initial Quantity | K2: Claim Loss and damge Quantity | L2: Claim Quantity2 | M2: NC number | N2: QTY Quality decision as local sale (wet bags) | O2: Short | P2: Reject | Q2: Hight polish | R2: Torn bags decision as Repacking | S2: loss | T2: Waste Bags | U2: Sound after repacking/bags | V2: loss | W2: Wet Bags | X2: Sound after repacking/bags | Y2: Claim Loss and damge Quantity | Z2: Unit Value - USD | AA2: Total defect QTY Value - USD | AB2: Wet bags | AC2: Unit price - SDG | AD2: Total Sale Value - SDG | AE2: Unit Value - USD | AF2: Total Wet Sale Value - USD | AG2: Wast bags | AH2: Unit price - SDG | AI2: Total Sale Value - SDG | AJ2: Unit Value - USD | AK2: Total Waste Sale Value - USD | AL2: Exchange Rate | AM2: Total Wet/Waste Sale Value - USD | AN2: Total Claim value | AO2: Hight polish | AP2: wet bag | AQ2: loss | AR2: Short | AS2: Reject | AT2: Waste unit price SDG | AU2: Wet/Downgrade unit price SDG | AV2: Wast value | AW2: Wet Value | AX2: Total Value SDG | AY2: Claim value before deduct local sale value | AZ2: Different | BA2: Unit | BB2: Cause of Loss | BC2: Insurance Type | BD2: Type | BE2: Detailed Description | BF2: Available documents | BG2: Unit Cost USD | BH2: Total Value USD | BI2: Unit Cost - SDG | BJ2: Total Value SDG | BK2: STD Cost-SDG | BL2: STD Value-SDG | BM2: Compensation Value | BN2: Exchange Rate | BO2: Compensation Status | BP2: System Status | BQ2: Follow Up Person | BR2: Period Type | BS2: Report by | BT2: Remark | BU2: Claim Status | BV2: Status | BW2: Status Update | BX2: Claim Value USD | BY2: Compensation Value USD | BZ2: Different | CA2: % of different | CB2: Remark of different | CC2: Remark | CD2: Repacking status
A3: 45603 | B3: =TEXT(A3,"MMM") -> Nov | C3: =YEAR(A3) -> 2024 | D3: 1 | E3: 3100033205A | F3: XI | G3: PZU-Bond area | H3: LE0001 | I3: LENTIL TAT 20KG | J3: 0 | K3: =N3+O3+P3+S3+T3+V3+W3 -> 0 | L3: 0 | M3: Zero QTY | N3: 0 | O3: 0 | P3: 0 | Q3: 0 | R3: 0 | S3: 0 | T3: 0 | U3: =R3-S3-T3 -> 0 | X3: =Q3-V3-W3 -> 0 | Y3: =N3+O3+P3+S3+T3+V3+W3 -> 0 | Z3: 0 | AA3: =Y3*Z3 -> 0 | AB3: =N3+W3 -> 0 | AF3: 0 | AG3: =T3 -> 0 | AK3: 0 | AL3: 0 | AM3: =AF3+AK3 -> 0 | AN3: =AA3-AM3 -> 0 | AO3: 0 | AR3: 0 | AS3: 0 | AY3: =VLOOKUP(E3,Table1[[BL NO.]:[Total Value USD]],21,0) -> 0 | AZ3: =AN3-AY3 -> 0 | BA3: 20KG BAGS | BB3: Import Container Damage/Short | BC3: Marine Insuranse | BD3: Import | BE3: Final inspection report, which confirms that there are no damaged bags as previously reported Container NO:FYCU7233921, BL NO:3100033205A | BF3: CIS report | BG3: 0 | BH3: =BG3*K3 -> 0 | BI3: 0 | BJ3: =BI3*L3 -> 0 | BK3: 0 | BL3: =BK3*L3 -> 0 | BM3: =BY3 -> 0 | BN3: 0 | BO3: No claim required (Zero loss) | BP3: N/A | BQ3: Ajay/Limitz | BR3: Post-War | BS3: Rawan | BU3: Accept | BV3: Close | BW3: No cargo damage | BX3: =BH3 -> 0 | BY3: 0 | BZ3: =BX3-BY3 -> 0 | CA3: =(BY3/BX3-1)*-1 -> #DIV/0! | CB3: No cargo damage
A4: 45603 | B4: =TEXT(A4,"MMM") -> Nov | C4: =YEAR(A4) -> 2024 | D4: 2 | E4: XERNSAPSZU14324. | F4: XI | G4: PZU-Bond area | H4: RC0004 | I4: RICE LONG ELNGM 20K | J4: 215 | K4: =N4+O4+P4+S4+T4+V4+W4 -> 215 | L4: 215 | M4: Not found | N4: 215 | O4: 0 | P4: 0 | Q4: 0 | R4: 0 | S4: 0 | T4: 0 | U4: =R4-S4-T4 -> 0 | X4: =Q4-V4-W4 -> 0 | Y4: =N4+O4+P4+S4+T4+V4+W4 -> 215 | Z4: 11.609302 | AA4: =Y4*Z4 -> 2496 | AB4: =N4+W4 -> 215 | AF4: =AD4/AL4 -> 0 | AG4: =T4 -> 0 | AK4: =AI4/AL4 -> 0 | AL4: 2372 | AM4: =AF4+AK4 -> 0 | AN4: =AA4-AM4 -> 2496 | AO4: 0 | AR4: 0 | AS4: 0 | AY4: =VLOOKUP(E4,Table1[[BL NO.]:[Total Value USD]],21,0) -> 2496 | AZ4: =AN4-AY4 -> 0 | BA4: 20KG BAGS | BB4: Import Container Damage/Short | BC4: Marine Insuranse | BD4: Import | BE4: Shipment arrived Bond Area, container NO: JZPU1111481, BL XERNSAPSZU14324. The damage quantity of rice in 20kg bags is (215 bags 20KG) noted in wet and damage condition. We have received 50% of claim amount after the standard deduction (as per the policy) from insurance company. From insurance side they have made payment and closed their file, amount received is $1248. | BF4: CIS report/Photo | BG4: 11.609302 | BH4: =BG4*K4 -> 2496 | BI4: 34000 | BJ4: =BI4*L4 -> 7310000 | BK4: 30750 | BL4: =BK4*L4 -> 6611250 | BM4: =BY4 -> 1248 | BN4: 2372 | BO4: Compensated | BP4: Adjusted | BQ4: Ajay/Shijil | BR4: Post-War | BS4: Rawan | BU4: Accept | BV4: Close | BW4: Insurance compensation | BX4: 2496 | BY4: 1248 | BZ4: =BX4-BY4 -> 1248 | CA4: =(BY4/BX4-1)*-1 -> 0.5 | CB4: As Shijil Email, We have received 50% of claim amount after the standard deduction (as per the policy) from insurance company. | CC4: As Shijil Email, We have received 50% of claim amount after the standard deduction (as per the policy) from insurance company.
A5: 45630 | B5: =TEXT(A5,"MMM") -> Dec | C5: =YEAR(A5) -> 2024 | D5: 3 | E5: 245672578 | F5: XI | G5: PZU-Bond area | H5: LE0001 | I5: LENTIL TAT 20KG | J5: 0 | K5: =N5+O5+P5+S5+T5+V5+W5 -> 0 | L5: 0 | M5: Zero QTY | N5: 0 | O5: 0 | P5: 0 | Q5: 0 | R5: 0 | S5: 0 | T5: 0 | U5: =R5-S5-T5 -> 0 | X5: =Q5-V5-W5 -> 0 | Y5: =N5+O5+P5+S5+T5+V5+W5 -> 0 | Z5: 0 | AA5: =Y5*Z5 -> 0 | AB5: =N5+W5 -> 0 | AF5: 0 | AG5: =T5 -> 0 | AK5: 0 | AL5: 0 | AM5: =AF5+AK5 -> 0 | AN5: =AA5-AM5 -> 0 | AO5: 0 | AR5: 0 | AS5: 0 | AY5: =VLOOKUP(E5,Table1[[BL NO.]:[Total Value USD]],21,0) -> 0 | AZ5: =AN5-AY5 -> 0 | BA5: 20KG BAGS | BB5: Import Container Damage/Short | BC5: Marine Insuranse | BD5: Import | BE5: Final inspection report, which confirms that there are no damaged bags as previously reported Container NO: CAAU6382276 /BL 245672578 | BF5: CIS report | BG5: 0 | BH5: =BG5*K5 -> 0 | BI5: 0 | BJ5: =BI5*L5 -> 0 | BK5: 0 | BL5: =BK5*L5 -> 0 | BM5: =BY5 -> 0 | BN5: 0 | BO5: No claim required (Zero loss) | BP5: N/A | BQ5: Ajay/Limitz | BR5: Post-War | BS5: Rawan | BU5: Accept | BV5: Close | BW5: No cargo damage | BX5: =BH5 -> 0 | BY5: 0 | BZ5: =BX5-BY5 -> 0 | CA5: =(BY5/BX5-1)*-1 -> #DIV/0! | CB5: No cargo damage
A6: 45630 | B6: =TEXT(A6,"MMM") -> Dec | C6: =YEAR(A6) -> 2024 | D6: 4 | E6: 245672856 | F6: XI | G6: PZU-Bond area | H6: LE0001 | I6: LENTIL TAT 20KG | J6: 0 | K6: =N6+O6+P6+S6+T6+V6+W6 -> 0 | L6: 0 | M6: Zero QTY | N6: 0 | O6: 0 | P6: 0 | Q6: 0 | R6: 0 | S6: 0 | T6: 0 | U6: =R6-S6-T6 -> 0 | X6: =Q6-V6-W6 -> 0 | Y6: =N6+O6+P6+S6+T6+V6+W6 -> 0 | Z6: 0 | AA6: =Y6*Z6 -> 0 | AB6: =N6+W6 -> 0 | AF6: 0 | AG6: =T6 -> 0 | AK6: 0 | AL6: 0 | AM6: =AF6+AK6 -> 0 | AN6: =AA6-AM6 -> 0 | AO6: 0 | AR6: 0 | AS6: 0 | AY6: =VLOOKUP(E6,Table1[[BL NO.]:[Total Value USD]],21,0) -> 0 | AZ6: =AN6-AY6 -> 0 | BA6: 20KG BAGS | BB6: Import Container Damage/Short | BC6: Marine Insuranse | BD6: Import | BE6: Final inspection report, which confirms that there are no damaged bags as previously reported Container NO:MSKU0899606 /BL 245672856 | BF6: CIS report | BG6: 0 | BH6: =BG6*K6 -> 0 | BI6: 0 | BJ6: =BI6*L6 -> 0 | BK6: 0 | BL6: =BK6*L6 -> 0 | BM6: =BY6 -> 0 | BN6: 0 | BO6: No claim required (Zero loss) | BP6: N/A | BQ6: Ajay/Limitz | BR6: Post-War | BS6: Rawan | BU6: Accept | BV6: Close | BW6: No cargo damage | BX6: =BH6 -> 0 | BY6: 0 | BZ6: =BX6-BY6 -> 0 | CA6: =(BY6/BX6-1)*-1 -> #DIV/0! | CB6: No cargo damage
A7: 45630 | B7: =TEXT(A7,"MMM") -> Dec | C7: =YEAR(A7) -> 2024 | D7: 4 | E7: 245672856 | F7: XI | G7: PZU-Bond area | H7: LE0001 | I7: LENTIL TAT 20KG | J7: 21 | K7: =N7+O7+P7+S7+T7+V7+W7 -> 21 | L7: 21 | M7: Not found | N7: 21 | O7: 0 | P7: 0 | Q7: 0 | R7: 0 | S7: 0 | T7: 0 | U7: =R7-S7-T7 -> 0 | X7: =Q7-V7-W7 -> 0 | Y7: =N7+O7+P7+S7+T7+V7+W7 -> 21 | Z7: 20.68 | AA7: =Y7*Z7 -> 434.28 | AB7: =N7+W7 -> 21 | AF7: =AD7/AL7 -> 0 | AG7: =T7 -> 0 | AK7: =AI7/AL7 -> 0 | AL7: 2350 | AM7: =AF7+AK7 -> 0 | AN7: =AA7-AM7 -> 434.28 | AO7: 0 | AR7: 0 | AS7: 0 | AY7: 434.28 | AZ7: =AN7-AY7 -> 0 | BA7: 20KG BAGS | BB7: Import Container Damage/Short | BC7: Marine Insuranse | BD7: Import | BE7: Shipment arrived Bond Area, Container NO: MVIU0022134 /BL 245672856-The damage quantity of rice in 20kg bags is (21 bags 20KG), having received 434,28 USD being the insurance claim amount. | BF7: CIS report/LOP | BG7: 20.68 | BH7: =BG7*K7 -> 434.28 | BI7: =BG7*BN7 -> 48598 | BJ7: =BI7*L7 -> 1020558 | BK7: 47408.368 | BL7: =BK7*L7 -> 995575.74 | BM7: =BY7 -> 434.28 | BN7: 2350 | BO7: Compensated | BP7: Adjusted | BQ7: Ajay/Limitz | BR7: Post-War | BS7: Rawan | BU7: Accept | BV7: Close | BW7: Insurance compensation | BX7: =BH7 -> 434.28 | BY7: 434.28 | BZ7: =BX7-BY7 -> 0 | CA7: =(BY7/BX7-1)*-1 -> 0 | CB7: Insurance compensated
A8: 45636 | B8: =TEXT(A8,"MMM") -> Dec | C8: =YEAR(A8) -> 2024 | D8: 5 | E8: XERNSAPSZU1462425 | F8: XI | G8: PZU-Bond area | H8: RC0004 | I8: RICE LONG ELNGM 20K | J8: 25 | K8: =N8+O8+P8+S8+T8+V8+W8 -> 25 | L8: 25 | M8: Not found | N8: 25 | O8: 0 | P8: 0 | Q8: 0 | R8: 0 | S8: 0 | T8: 0 | U8: =R8-S8-T8 -> 0 | X8: =Q8-V8-W8 -> 0 | Y8: =N8+O8+P8+S8+T8+V8+W8 -> 25 | Z8: 13.327962 | AA8: =Y8*Z8 -> 333.19904 | AB8: =N8+W8 -> 25 | AF8: =AD8/AL8 -> 0 | AG8: =T8 -> 0 | AK8: =AI8/AL8 -> 0 | AL8: 2350 | AM8: =AF8+AK8 -> 0 | AN8: =AA8-AM8 -> 333.19904 | AO8: 0 | AR8: 0 | AS8: 0 | AY8: =VLOOKUP(E8,Table1[[BL NO.]:[Total Value USD]],21,0) -> 333.19904 | AZ8: =AN8-AY8 -> 0 | BA8: 20KG BAGS | BB8: Import Container Damage/Short | BC8: Marine Insuranse | BD8: Import | BE8: Shipment arrived Bond Area, Container NO:TEMU4187019 /BL XERNSAPSZU1462425 (14 bags), XERNSAPSZU1472425(11 bags) Total (25 bags). The damage quantity of rice in 20kg bags is 25 bags 20KG), case reject There is 0.5% excess payable for each claim (in this case $1826.55). Claim Value of 25 bags is less than 0.5% excess value hence insurance company has closed the file. | BF8: CIS report/LOP | BG8: 13.327962 | BH8: =BG8*K8 -> 333.19904 | BI8: 31320.71 | BJ8: =BI8*L8 -> 783017.75 | BK8: 29520.555 | BL8: =BK8*L8 -> 738013.89 | BM8: =BY8 -> 0 | BN8: 2350 | BO8: Loss | BP8: Adjusted | BQ8: Ajay/Shijil | BR8: Post-War | BS8: Rawan | BU8: Accept | BV8: Close | BW8: Less than deductable | BX8: =BH8 -> 333.19904 | BY8: 0 | BZ8: =BX8-BY8 -> 333.19904 | CA8: =(BY8/BX8-1)*-1 -> 1 | CB8: Less than deductable (0.5%)
A9: 45682 | B9: =TEXT(A9,"MMM") -> Jan | C9: =YEAR(A9) -> 2025 | D9: 6 | E9: 247070297 | F9: XI | G9: PZU | H9: LE0001 | I9: LENTIL TAT 20KG | J9: 45 | K9: =N9+O9+P9+S9+T9+V9+W9 -> 45 | L9: 45 | M9: Short | N9: 0 | O9: 45 | P9: 0 | Q9: 0 | R9: 0 | S9: 0 | T9: 0 | U9: =R9-S9-T9 -> 0 | X9: =Q9-V9-W9 -> 0 | Y9: =N9+O9+P9+S9+T9+V9+W9 -> 45 | Z9: 20.135917 | AA9: =Y9*Z9 -> 906.11628 | AB9: =N9+W9 -> 0 | AF9: =AD9/AL9 -> 0 | AG9: =T9 -> 0 | AK9: =AI9/AL9 -> 0 | AL9: 2582.45 | AM9: =AF9+AK9 -> 0 | AN9: =AA9-AM9 -> 906.11628 | AO9: 0 | AR9: 45 | AS9: 0 | AY9: =VLOOKUP(E9,Table1[[BL NO.]:[Total Value USD]],21,0) -> 906.11628 | AZ9: =AN9-AY9 -> 0 | BA9: 20KG BAGS | BB9: Import Container Damage/Short | BC9: Marine Insuranse | BD9: Import | BE9: 45 bags found shortage at container BL:247070297 - MAEU247070297 | BF9: CIS report/LOP | BG9: 20.135917 | BH9: =BG9*K9 -> 906.11628 | BI9: 52000 | BJ9: =BI9*L9 -> 2340000 | BK9: 48417.057 | BL9: =BK9*L9 -> 2178767.6 | BM9: =BY9 -> 0 | BN9: 2582.45 | BO9: Pending | BP9: Adjusted | BQ9: Ajay/Limitz | BR9: Post-War | BS9: Rawan | BU9: Pending | BV9: Pending | BW9: Case submitted/ Waiting Insurance feedback | BX9: =BH9 -> 906.11628 | BY9: 0 | BZ9: =BX9-BY9 -> 906.11628 | CA9: =(BY9/BX9-1)*-1 -> 1 | CB9: Waiting Feedback
A10: 45701 | B10: =TEXT(A10,"MMM") -> Feb | C10: =YEAR(A10) -> 2025 | D10: 7 | E10: 248620904 | F10: XI | G10: PZU-Bond area | H10: LE0001 | I10: LENTIL TAT 20KG | J10: 54 | K10: =N10+O10+P10+S10+T10+V10+W10 -> 54 | L10: 54 | M10: Short | N10: 0 | O10: 54 | P10: 0 | Q10: 0 | R10: 0 | S10: 0 | T10: 0 | U10: =R10-S10-T10 -> 0 | X10: =Q10-V10-W10 -> 0 | Y10: =N10+O10+P10+S10+T10+V10+W10 -> 54 | Z10: 20.02 | AA10: =Y10*Z10 -> 1081.08 | AB10: =N10+W10 -> 0 | AF10: =AD10/AL10 -> 0 | AG10: =T10 -> 0 | AK10: =AI10/AL10 -> 0 | AL10: 2582.45 | AM10: =AF10+AK10 -> 0 | AN10: =AA10-AM10 -> 1081.08 | AO10: 0 | AR10: 54 | AS10: 0 | AY10: =VLOOKUP(E10,Table1[[BL NO.]:[Total Value USD]],21,0) -> 1081.08 | AZ10: =AN10-AY10 -> 0 | BA10: 20KG BAGS | BB10: Import Container Damage/Short | BC10: Marine Insuranse | BD10: Import | BE10: 54 bags found shortage at container BL:248620904 | BF10: CIS report/LOP | BG10: 20.02 | BH10: =BG10*K10 -> 1081.08 | BI10: 51700.649 | BJ10: =BI10*L10 -> 2791835 | BK10: 52451.812 | BL10: =BK10*L10 -> 2832397.8 | BM10: =BY10 -> 1081.08 | BN10: 2582.45 | BO10: Compensated | BP10: Adjusted | BQ10: Ajay/Limitz | BR10: Post-War | BS10: Rawan | BU10: Accept | BV10: Close | BW10: Insurance compensation | BX10: =BH10 -> 1081.08 | BY10: 1081.08 | BZ10: =BX10-BY10 -> 0 | CA10: =(BY10/BX10-1)*-1 -> 0 | CB10: Insurance compensated
A11: 45703 | B11: =TEXT(A11,"MMM") -> Feb | C11: =YEAR(A11) -> 2025 | D11: 8 | E11: 248619667 | F11: XI | G11: PZU-Bond area | H11: LE0001 | I11: LENTIL TAT 20KG | J11: 107 | K11: =N11+O11+P11+S11+T11+V11+W11 -> 107 | L11: 107 | M11: Short | N11: 0 | O11: 107 | P11: 0 | Q11: 0 | R11: 0 | S11: 0 | T11: 0 | U11: =R11-S11-T11 -> 0 | X11: =Q11-V11-W11 -> 0 | Y11: =N11+O11+P11+S11+T11+V11+W11 -> 107 | Z11: 20.02 | AA11: =Y11*Z11 -> 2142.14 | AB11: =N11+W11 -> 0 | AF11: =AD11/AL11 -> 0 | AG11: =T11 -> 0 | AK11: =AI11/AL11 -> 0 | AL11: 2582.45 | AM11: =AF11+AK11 -> 0 | AN11: =AA11-AM11 -> 2142.14 | AO11: 0 | AR11: 107 | AS11: 0 | AY11: =VLOOKUP(E11,Table1[[BL NO.]:[Total Value USD]],21,0) -> 2142.14 | AZ11: =AN11-AY11 -> 0 | BA11: 20KG BAGS | BB11: Import Container Damage/Short | BC11: Marine Insuranse | BD11: Import | BE11: 107 bags found shortage at container BL:248619667 | BF11: CIS report/LOP | BG11: 20.02 | BH11: =BG11*K11 -> 2142.14 | BI11: 51700.649 | BJ11: =BI11*L11 -> 5531969.4 | BK11: 52451.812 | BL11: =BK11*L11 -> 5612343.9 | BM11: =BY11 -> 2142.14 | BN11: 2582.45 | BO11: Compensated | BP11: Adjusted | BQ11: Ajay/Limitz | BR11: Post-War | BS11: Rawan | BU11: Accept | BV11: Close | BW11: Insurance compensation | BX11: =BH11 -> 2142.14 | BY11: 2142.14 | BZ11: =BX11-BY11 -> 0 | CA11: =(BY11/BX11-1)*-1 -> 0 | CB11: Insurance compensated
A12: 45713 | B12: =TEXT(A12,"MMM") -> Feb | C12: =YEAR(A12) -> 2025 | D12: 9 | E12: 248620255 | F12: XI | G12: PZU-Bond area | H12: LE0001 | I12: LENTIL TAT 20KG | J12: 55 | K12: =N12+O12+P12+S12+T12+V12+W12 -> 55 | L12: 55 | M12: Short | N12: 0 | O12: 55 | P12: 0 | Q12: 0 | R12: 0 | S12: 0 | T12: 0 | U12: =R12-S12-T12 -> 0 | X12: =Q12-V12-W12 -> 0 | Y12: =N12+O12+P12+S12+T12+V12+W12 -> 55 | Z12: 20.02 | AA12: =Y12*Z12 -> 1101.1 | AB12: =N12+W12 -> 0 | AF12: =AD12/AL12 -> 0 | AG12: =T12 -> 0 | AK12: =AI12/AL12 -> 0 | AL12: 2582.45 | AM12: =AF12+AK12 -> 0 | AN12: =AA12-AM12 -> 1101.1 | AO12: 0 | AR12: 55 | AS12: 0 | AY12: =VLOOKUP(E12,Table1[[BL NO.]:[Total Value USD]],21,0) -> 1101.1 | AZ12: =AN12-AY12 -> 0 | BA12: 20KG BAGS | BB12: Import Container Damage/Short | BC12: Marine Insuranse | BD12: Import | BE12: 55 bags found shortage at container BL:248620255 | BF12: CIS report/LOP | BG12: =BH12/L12 -> 20.02 | BH12: =BG12*K12 -> 0 | BI12: 51700.649 | BJ12: =BI12*L12 -> 2843535.7 | BK12: 52451.812 | BL12: =BK12*L12 -> 2884849.7 | BM12: =BY12 -> 1101.1 | BN12: 2582.45 | BO12: Compensated | BP12: Adjusted | BQ12: Ajay/Limitz | BR12: Post-War | BS12: Rawan | BU12: Accept | BV12: Close | BW12: Insurance compensation | BX12: =BH12 -> 1101.1 | BY12: 1101.1 | BZ12: =BX12-BY12 -> 0 | CA12: =(BY12/BX12-1)*-1 -> 0 | CB12: Insurance compensated
A13: 45714 | B13: =TEXT(A13,"MMM") -> Feb | C13: =YEAR(A13) -> 2025 | D13: 10 | E13: 248621429 | F13: XI | G13: PZU-Bond area | H13: LE0001 | I13: LENTIL TAT 20KG | J13: 30 | K13: =N13+O13+P13+S13+T13+V13+W13 -> 30 | L13: 30 | M13: Short | N13: 0 | O13: 30 | P13: 0 | Q13: 0 | R13: 0 | S13: 0 | T13: 0 | U13: =R13-S13-T13 -> 0 | X13: =Q13-V13-W13 -> 0 | Y13: =N13+O13+P13+S13+T13+V13+W13 -> 30 | Z13: 20 | AA13: =Y13*Z13 -> 600 | AB13: =N13+W13 -> 0 | AF13: =AD13/AL13 -> 0 | AG13: =T13 -> 0 | AK13: =AI13/AL13 -> 0 | AL13: 2582.45 | AM13: =AF13+AK13 -> 0 | AN13: =AA13-AM13 -> 600 | AO13: 0 | AR13: 30 | AS13: 0 | AY13: =VLOOKUP(E13,Table1[[BL NO.]:[Total Value USD]],21,0) -> 600 | AZ13: =AN13-AY13 -> 0 | BA13: 20KG BAGS | BB13: Import Container Damage/Short | BC13: Marine Insuranse | BD13: Import | BE13: 30 bags found shortage at container BL:248621429 | BF13: CIS report/LOP | BG13: =BH13/L13 -> 20 | BH13: =BG13*K13 -> 0 | BI13: =BG13*BN13 -> 51649 | BJ13: =BI13*L13 -> 1549470 | BK13: 52451.812 | BL13: =BK13*L13 -> 1573554.4 | BM13: =BY13 -> 600 | BN13: 2582.45 | BO13: Compensated | BP13: Adjusted | BQ13: Ajay/Limitz | BR13: Post-War | BS13: Rawan | BU13: Accept | BV13: Close | BW13: Insurance compensation | BX13: =BH13 -> 600 | BY13: 600 | BZ13: =BX13-BY13 -> 0 | CA13: =(BY13/BX13-1)*-1 -> 0 | CB13: Insurance compensated
